Workbook

Sheet वर्गशिक्षक
B1: क्रांतिवीर वसंतराव नारायणराव नाईक शिक्षण प्रसारक संस्था,नाशिक संचलित
B2: माध्यमिक व उच्च माध्यमिक विद्यामंदिर,राजापूर ता.येवला जि.नाशिक
B3: 5 वी ते 10 वर्गशिक्षक/ वर्गशिक्षिका यादी
B4: अ.नं. | C4: इयत्ता | D4: तुकडी | E4: वर्गशिक्षक / वर्गशिक्षिका | F4: मोबाईल नंबर
B5: 1 | C5: पाचवी | D5: अ | E5: श्री.दराडे ज्ञानेश्वर दत्तु | F5: 8888770916
B6: 2 | C6: पाचवी | D6: ब | E6: श्री.बोडखे रमेश साहेबराव | F6: 9923087374
B7: 3 | C7: सहावी | D7: अ | E7: श्री.दराडे सुनिल लक्ष्मण | F7: 9765230345
B8: 4 | C8: सहावी | D8: ब | E8: श्री.सानप बाळासाहेब दगू | F8: 9604860467
B9: 5 | C9: सातवी | D9: अ | E9: श्रीम.गिते ज्योती अशोक | F9: 8459841811
B10: 6 | C10: सातवी | D10: ब | E10: श्री.ठोंबरे लक्ष्मण शंकर | F10: 9960813611
B11: 7 | C11: आठवी | D11: अ | E11: श्री.जगताप संदिप दादाजी | F11: 7276009493
B12: 8 | C12: आठवी | D12: ब | E12: श्री.कुलकर्णी मंदार लक्ष्मीकांत | F12: 8805171346
B13: 9 | C13: नववी | D13: अ | E13: श्री.काकड रमेश भागवत | F13: 8788467725
B14: 10 | C14: नववी | D14: ब | E14: श्री.सानप गोकुळ बबन | F14: 8317254474
B15: 11 | C15: दहावी | D15: अ | E15: श्री.पानसरे वसंत वाल्मिक | F15: 8788064036
B16: 12 | C16: दहावी | D16: ब | E16: श्री.गडाख शरद सुधाकर | F16: 9960639725
... B22: 18 | C22: बारावी विज्ञान | D22: - | E22: श्री.सोनवणे गणेश मदन | F22: 8830109791

Sheet वर्गवेळापत्रक
B1: वेळापत्रक | J1: वेळापत्रक | R1: वेळापत्रक | Z1: वेळापत्रक | AH1: वेळापत्रक | AP1: वेळापत्रक
B2: इयत्ताः- पाचवी तुकडीः- अ वर्गशिक्षकः- श्री.दराडे ज्ञानेश्वर दत्तु | J2: इयत्ताः- सहावी तुकडीः- अ वर्गशिक्षकः- श्री.दराडे सुनिल लक्ष्मण | R2: इयत्ताः- सातवी तुकडीः- अ वर्गशिक्षकः- श्रीम.गिते ज्योती अशोक | Z2: इयत्ताः- आठवी तुकडीः- अ वर्गशिक्षकः- श्री.जगताप संदिप दादाजी | AH2: इयत्ताः- नववी तुकडीः- अ वर्गशिक्षकः- श्री.काकड रमेश भागवत | AP2: इयत्ताः- दहावी तुकडीः- अ वर्गशिक्षकः- श्री.पानसरे वसंत वाल्मिक
B3: अ.नं. | C3: सोमवार | D3: मंगळवार | E3: बुधवार | F3: गुरूवार | G3: शुक्रवार | H3: शनिवार | J3: अ.नं. | K3: सोमवार | L3: मंगळवार | M3: बुधवार | N3: गुरूवार | O3: शुक्रवार | P3: शनिवार | R3: अ.नं. | S3: सोमवार | T3: मंगळवार | U3: बुधवार | V3: गुरूवार | W3: शुक्रवार | X3: शनिवार | Z3: अ.नं. | AA3: सोमवार | AB3: मंगळवार | AC3: बुधवार | AD3: गुरूवार | AE3: शुक्रवार | AF3: शनिवार | AH3: अ.नं. | AI3: सोमवार | AJ3: मंगळवार | AK3: बुधवार | AL3: गुरूवार | AM3: शुक्रवार | AN3: शनिवार | AP3: अ.नं. | AQ3: सोमवार | AR3: मंगळवार | AS3: बुधवार | AT3: गुरूवार | AU3: शुक्रवार | AV3: शनिवार
B4: 1 | C4: गणित | D4: गणित | E4: गणित | F4: गणित | G4: गणित | H4: गणित | J4: 1 | K4: हिंदी | L4: हिंदी | M4: हिंदी | N4: हिंदी | O4: हिंदी | P4: हिंदी | R4: 1 | S4: गणित | T4: गणित | U4: गणित | V4: गणित | W4: गणित | X4: गणित | Z4: 1 | AA4: इंग्रजी | AB4: इंग्रजी | AC4: इंग्रजी | AD4: इंग्रजी | AE4: इंग्रजी | AF4: इंग्रजी | AH4: 1 | AI4: मराठी | AJ4: मराठी | AK4: मराठी | AL4: मराठी | AM4: मराठी | AN4: मराठी | AP4: 1 | AQ4: मराठी | AR4: मराठी | AS4: मराठी | AT4: मराठी | AU4: मराठी | AV4: मराठी
C5: दराडे डी.डी. | D5: दराडे डी.डी. | E5: दराडे डी.डी. | F5: दराडे डी.डी. | G5: दराडे डी.डी. | H5: दराडे डी.डी. | K5: दराडे एस.एल. | L5: दराडे एस.एल. | M5: दराडे एस.एल. | N5: दराडे एस.एल. | O5: दराडे एस.एल. | P5: दराडे एस.एल. | S5: गिते जे.ए. | T5: गिते जे.ए. | U5: गिते जे.ए. | V5: गिते जे.ए. | W5: गिते जे.ए. | X5: गिते जे.ए. | AA5: जगताप एस.डी. | AB5: जगताप एस.डी. | AC5: जगताप एस.डी. | AD5: जगताप एस.डी. | AE5: जगताप एस.डी. | AF5: जगताप एस.डी. | AI5: काकड आर.बी. | AJ5: काकड आर.बी. | AK5: काकड आर.बी. | AL5: काकड आर.बी. | AM5: काकड आर.बी. | AN5: काकड आर.बी. | AQ5: पानसरे व्ही.व्ही. | AR5: पानसरे व्ही.व्ही. | AS5: पानसरे व्ही.व्ही. | AT5: पानसरे व्ही.व्ही. | AU5: पानसरे व्ही.व्ही. | AV5: पानसरे व्ही.व्ही.
B6: 2 | C6: हिंदी | D6: हिंदी | E6: हिंदी | F6: हिंदी | G6: शा.शिक्षण | H6: शा.शिक्षण | J6: 2 | K6: मराठी | L6: मराठी | M6: मराठी | N6: मराठी | O6: कला | P6: कला | R6: 2 | S6: कला | T6: कला | U6: कला | V6: कला | W6: हिंदी | X6: हिंदी | Z6: 2 | AA6: गणित | AB6: गणित | AC6: गणित | AD6: गणित | AE6: गणित | AF6: गणित | AH6: 2 | AI6: इंग्रजी | AJ6: इंग्रजी | AK6: इंग्रजी | AL6: इंग्रजी | AM6: इंग्रजी | AN6: इंग्रजी | AP6: 2 | AQ6: गणित | AR6: गणित | AS6: गणित | AT6: गणित | AU6: गणित | AV6: गणित
C7: सानप बी.डी. | D7: सानप बी.डी. | E7: सानप बी.डी. | F7: सानप बी.डी. | G7: वाघ आर.बी. | H7: वाघ आर.बी. | K7: काकड आर.बी. | L7: काकड आर.बी. | M7: काकड आर.बी. | N7: काकड आर.बी. | O7: वाघ एस.एन. | P7: वाघ एस.एन. | S7: वाघ एस.एन. | T7: वाघ एस.एन. | U7: वाघ एस.एन. | V7: वाघ एस.एन. | W7: वाघ व्ही.व्ही. | X7: वाघ व्ही.व्ही. | AA7: गिते जे.ए. | AB7: गिते जे.ए. | AC7: गिते जे.ए. | AD7: गिते जे.ए. | AE7: गिते जे.ए. | AF7: गिते जे.ए. | AI7: जगताप एस.डी. | AJ7: जगताप एस.डी. | AK7: जगताप एस.डी. | AL7: जगताप एस.डी. | AM7: जगताप एस.डी. | AN7: जगताप एस.डी. | AQ7: गडाख एस.एस. | AR7: गडाख एस.एस. | AS7: गडाख एस.एस. | AT7: गडाख एस.एस. | AU7: गडाख एस.एस. | AV7: गडाख एस.एस.
B8: 3 | C8: मराठी | D8: मराठी | E8: मराठी | F8: मराठी | G8: मराठी | H8: मराठी | J8: 3 | K8: गणित | L8: गणित | M8: गणित | N8: गणित | O8: गणित | P8: गणित | R8: 3 | S8: हिंदी | T8: हिंदी | U8: हिंदी | V8: हिंदी | W8: शा.शिक्षण | X8: कार्यशिक्षण | Z8: 3 | AA8: मराठी | AB8: मराठी | AC8: मराठी | AD8: मराठी | AE8: मराठी | AF8: मराठी | AH8: 3 | AI8: हिंदी | AJ8: हिंदी | AK8: हिंदी | AL8: हिंदी | AM8: हिंदी | AN8: गणित | AP8: 3 | AQ8: इंग्रजी | AR8: इंग्रजी | AS8: इंग्रजी | AT8: इंग्रजी | AU8: इंग्रजी | AV8: इंग्रजी
C9: सानप जी.बी. | D9: सानप जी.बी. | E9: सानप जी.बी. | F9: सानप जी.बी. | G9: सानप जी.बी. | H9: सानप जी.बी. | K9: दराडे डी.डी. | L9: दराडे डी.डी. | M9: दराडे डी.डी. | N9: दराडे डी.डी. | O9: दराडे डी.डी. | P9: दराडे डी.डी. | S9: वाघ व्ही.व्ही. | T9: वाघ व्ही.व्ही. | U9: वाघ व्ही.व्ही. | V9: वाघ व्ही.व्ही. | W9: वाघ व्ही.व्ही. | X9: ठोंबरे एल.एस. | AA9: पानसरे व्ही.व्ही. | AB9: पानसरे व्ही.व्ही. | AC9: पानसरे व्ही.व्ही. | AD9: पानसरे व्ही.व्ही. | AE9: पानसरे व्ही.व्ही. | AF9: पानसरे व्ही.व्ही. | AI9: वाघ आर.बी. | AJ9: वाघ आर.बी. | AK9: वाघ आर.बी. | AL9: वाघ आर.बी. | AM9: वाघ आर.बी. | AN9: गिते जे.ए. | AQ9: घुगे एस.आर. | AR9: घुगे एस.आर. | AS9: घुगे एस.आर. | AT9: घुगे एस.आर. | AU9: घुगे एस.आर. | AV9: घुगे एस.आर.
B10: 4 | C10: परीसर 1 | D10: परीसर 1 | E10: परीसर 1 | F10: परीसर 1 | G10: परीसर 1 | H10: परीसर 1 | J10: 4 | K10: कला | L10: कला | M10: समाजशास्त्र | N10: समाजशास्त्र | O10: समाजशास्त्र | P10: समाजशास्त्र | R10: 4 | S10: इंग्रजी | T10: इंग्रजी | U10: इंग्रजी | V10: इंग्रजी | W10: इंग्रजी | X10: इंग्रजी | Z10: 4 | AA10: विज्ञान | AB10: विज्ञान | AC10: विज्ञान | AD10: विज्ञान | AE10: विज्ञान | AF10: विज्ञान | AH10: 4 | AI10: गणित | AJ10: गणित | AK10: गणित | AL10: गणित | AM10: गणित | AN10: गणित | AP10: 4 | AQ10: हिंदी | AR10: हिंदी | AS10: हिंदी | AT10: हिंदी | AU10: हिंदी | AV10: हिंदी
C11: दराडे डी.डी. | D11: दराडे डी.डी. | E11: दराडे डी.डी. | F11: दराडे डी.डी. | G11: दराडे डी.डी. | H11: दराडे डी.डी. | K11: वाघ एस.एन. | L11: वाघ एस.एन. | M11: सानप बी.डी. | N11: सानप बी.डी. | O11: सानप बी.डी. | P11: सानप बी.डी. | S11: घुगे एस.आर. | T11: घुगे एस.आर. | U11: घुगे एस.आर. | V11: घुगे एस.आर. | W11: घुगे एस.आर. | X11: घुगे एस.आर. | AA11: गडाख एस.एस. | AB11: गडाख एस.एस. | AC11: गडाख एस.एस. | AD11: गडाख एस.एस. | AE11: गडाख एस.एस. | AF11: गडाख एस.एस. | AI11: गिते जे.ए. | AJ11: गिते जे.ए. | AK11: गिते जे.ए. | AL11: गिते जे.ए. | AM11: गिते जे.ए. | AN11: गिते जे.ए. | AQ11: दराडे एस.एल. | AR11: दराडे एस.एल. | AS11: दराडे एस.एल. | AT11: दराडे एस.एल. | AU11: दराडे एस.एल. | AV11: दराडे एस.एल.
B12: ********* मधली सुट्टी ********* | J12: ********* मधली सुट्टी ********* | R12: ********* मधली सुट्टी ********* | Z12: ********* मधली सुट्टी ********* | AH12: ********* मधली सुट्टी ********* | AP12: ********* मधली सुट्टी *********
B13: 5 | C13: परीसर 2 | D13: परीसर 2 | E13: परीसर 2 | F13: परीसर 2 | G13: परीसर 2 | H13: कला | J13: 5 | K13: इंग्रजी | L13: इंग्रजी | M13: इंग्रजी | N13: इंग्रजी | O13: इंग्रजी | P13: शा.शिक्षण | R13: 5 | S13: मराठी | T13: मराठी | U13: मराठी | V13: मराठी | W13: मराठी | X13: मराठी | Z13: 5 | AA13: शा.शिक्षण | AB13: शा.शिक्षण | AC13: शा.शिक्षण | AD13: शा.शिक्षण | AE13: समाजशास्त्र | AF13: समाजशास्त्र | AH13: 5 | AI13: विज्ञान | AJ13: विज्ञान | AK13: इतिहास | AL13: इतिहास | AM13: इतिहास | AN13: इतिहास | AP13: 5 | AQ13: विज्ञान | AR13: विज्ञान | AS13: विज्ञान | AT13: विज्ञान | AU13: विज्ञान | AV13: गणित
C14: दराडे डी.डी. | D14: दराडे डी.डी. | E14: दराडे डी.डी. | F14: दराडे डी.डी. | G14: दराडे डी.डी. | H14: वाघ एस.एन. | K14: घुगे एस.आर. | L14: घुगे एस.आर. | M14: घुगे एस.आर. | N14: घुगे एस.आर. | O14: घुगे एस.आर. | P14: वाघ व्ही.व्ही. | S14: पानसरे व्ही.व्ही. | T14: पानसरे व्ही.व्ही. | U14: पानसरे व्ही.व्ही. | V14: पानसरे व्ही.व्ही. | W14: पानसरे व्ही.व्ही. | X14: पानसरे व्ही.व्ही. | AA14: वाघ व्ही.व्ही. | AB14: वाघ व्ही.व्ही. | AC14: वाघ व्ही.व्ही. | AD14: वाघ व्ही.व्ही. | AE14: काकड आर.बी. | AF14: काकड आर.बी. | AI14: गडाख एस.एस. | AJ14: गडाख एस.एस. | AK14: जगताप एस.डी. | AL14: जगताप एस.डी. | AM14: जगताप एस.डी. | AN14: जगताप एस.डी. | AQ14: गिते जे.ए. | AR14: गिते जे.ए. | AS14: गिते जे.ए. | AT14: गिते जे.ए. | AU14: गिते जे.ए. | AV14: गडाख एस.एस.
B15: 6 | C15: इंग्रजी | D15: इंग्रजी | E15: इंग्रजी | F15: इंग्रजी | G15: इंग्रजी | H15: कला | J15: 6 | K15: शा.शिक्षण | L15: शा.शिक्षण | M15: समाजशास्त्र | N15: समाजशास्त्र | O15: मराठी | P15: मराठी | R15: 6 | S15: विज्ञान | T15: विज्ञान | U15: विज्ञान | V15: विज्ञान | W15: विज्ञान | X15: कार्यशिक्षण | Z15: 6 | AA15: हिंदी | AB15: हिंदी | AC15: हिंदी | AD15: हिंदी | AE15: हिंदी | AF15: हिंदी | AH15: 6 | AI15: जलसुरक्षा | AJ15: जलसुरक्षा | AK15: भूगोल | AL15: भूगोल | AM15: हिंदी | AN15: स्का./ गाईड | AP15: 6 | AQ15: इतिहास | AR15: इतिहास | AS15: इतिहास | AT15: इतिहास | AU15: स्का./गाईड | AV15: शा.शिक्षण
C16: चौधरी एस.बी. | D16: चौधरी एस.बी. | E16: चौधरी एस.बी. | F16: चौधरी एस.बी. | G16: चौधरी एस.बी. | H16: वाघ एस.एन. | K16: वाघ व्ही.व्ही. | L16: वाघ व्ही.व्ही. | M16: सानप बी.डी. | N16: सानप बी.डी. | O16: काकड आर.बी. | P16: काकड आर.बी. | S16: गडाख एस.एस. | T16: गडाख एस.एस. | U16: गडाख एस.एस. | V16: गडाख एस.एस. | W16: गडाख एस.एस. | X16: ठोंबरे एल.एस. | AA16: दराडे एस.एल. | AB16: दराडे एस.एल. | AC16: दराडे एस.एल. | AD16: दराडे एस.एल. | AE16: दराडे एस.एल. | AF16: दराडे एस.एल. | AI16: सानप बी.डी. | AJ16: सानप बी.डी. | AK16: पानसरे व्ही.व्ही. | AL16: पानसरे व्ही.व्ही. | AM16: वाघ आर.बी. | AN16: गिते एस.एस. | AQ16: काकड आर.बी. | AR16: काकड आर.बी. | AS16: काकड आर.बी. | AT16: काकड आर.बी. | AU16: ठोंबरे एस.एल. | AV16: वाघ व्ही.व्ही.
B17: 7 | C17: कला | D17: कार्यशिक्षण | E17: कार्यशिक्षण | F17: कार्यशिक्षण | G17: शा.शिक्षण | H17: शा.शिक्षण | J17: 7 | K17: विज्ञान | L17: विज्ञान | M17: विज्ञान | N17: विज्ञान | O17: विज्ञान | P17: शा.शिक्षण | R17: 7 | S17: गणित | T17: शा.शिक्षण | U17: शा.शिक्षण | V17: शा.शिक्षण | W17: समाजशास्त्र | X17: समाजशास्त्र | Z17: 7 | AA17: समाजशास्त्र | AB17: समाजशास्त्र | AC17: समाजशास्त्र | AD17: समाजशास्त्र | AE17: विज्ञान | AF17: गणित | AH17: 7 | AI17: विज्ञान | AJ17: विज्ञान | AK17: विज्ञान | AL17: विज्ञान | AM17: भूगोल | AN17: इंग्रजी | AP17: 7 | AQ17: भूगोल | AR17: विज्ञान | AS17: इंग्रजी | AT17: भूगोल | AU17: भूगोल | AV17: स्का./गाईड
C18: वाघ एस.एन. | D18: सानप जी.बी. | E18: सानप जी.बी. | F18: सानप जी.बी. | G18: वाघ आर.बी. | H18: वाघ आर.बी. | K18: दराडे डी.डी. | L18: दराडे डी.डी. | M18: दराडे डी.डी. | N18: दराडे डी.डी. | O18: दराडे डी.डी. | P18: वाघ व्ही.व्ही. | S18: गिते जे.ए. | T18: वाघ व्ही.व्ही. | U18: वाघ व्ही.व्ही. | V18: वाघ व्ही.व्ही. | W18: सानप जी.बी. | X18: सानप जी.बी. | AA18: काकड आर.बी. | AB18: काकड आर.बी. | AC18: काकड आर.बी. | AD18: काकड आर.बी. | AE18: गडाख एस.एस. | AF18: गिते जे.ए. | AI18: गडाख एस.एस. | AJ18: गडाख एस.एस. | AK18: गडाख एस.एस. | AL18: गडाख एस.एस. | AM18: पानसरे व्ही.व्ही. | AN18: जगताप एस.डी. | AQ18: दराडे एस.एल. | AR18: गिते जे.ए. | AS18: घुगे एस.आर. | AT18: दराडे एस.एल. | AU18: दराडे एस.एल. | AV18: ठोंबरे एस.एल.
B19: 8 | C19: परीसर 2 | D19: हिंदी | E19: हिंदी | F19: गणित | G19: इंग्रजी | H19: गणित | J19: 8 | K19: कार्यशिक्षण | L19: गणित | M19: विज्ञान | N19: इंग्रजी | O19: विज्ञान | P19: कार्यशिक्षण | R19: 8 | S19: विज्ञान | T19: समाजशास्त्र | U19: समाजशास्त्र | V19: समाजशास्त्र | W19: समाजशास्त्र | X19: विज्ञान | Z19: 8 | AA19: कार्यशिक्षण | AB19: कला | AC19: कला | AD19: कला | AE19: कला | AF19: कार्यशिक्षण | AH19: 8 | AI19: शा.शिक्षण | AJ19: शा.शिक्षण | AK19: शा.शिक्षण | AL19: जलसुरक्षा | AM19: विज्ञान | AN19: स्का./ गाईड | AP19: 8 | AQ19: जलसुरक्षा | AR19: जलसुरक्षा | AS19: जलसुरक्षा | AT19: शा.शिक्षण | AU19: शा.शिक्षण | AV19: विज्ञान
C20: दराडे डी.डी. | D20: सानप बी.डी. | E20: सानप बी.डी. | F20: दराडे डी.डी. | G20: चौधरी एस.बी. | H20: दराडे डी.डी. | K20: वाघ एस.एन. | L20: दराडे डी.डी. | M20: दराडे डी.डी. | N20: घुगे एस.आर. | O20: दराडे डी.डी. | P20: वाघ एस.एन. | S20: गडाख एस.एस. | T20: सानप जी.बी. | U20: सानप जी.बी. | V20: सानप जी.बी. | W20: सानप जी.बी. | X20: गडाख एस.एस. | AA20: काकड आर.बी. | AB20: वाघ एस.एन. | AC20: वाघ एस.एन. | AD20: वाघ एस.एन. | AE20: वाघ एस.एन. | AF20: काकड आर.बी. | AI20: वाघ आर.बी. | AJ20: वाघ आर.बी. | AK20: वाघ आर.बी. | AL20: सानप बी.डी. | AM20: गडाख एस.एस. | AN20: चौधरी एस.बी. | AQ20: घुगे एस.आर. | AR20: घुगे एस.आर. | AS20: घुगे एस.आर. | AT20: वाघ व्ही.व्ही. | AU20: वाघ व्ही.व्ही. | AV20: गिते जे.ए.
B22: वेळापत्रक | J22: वेळापत्रक | R22: वेळापत्रक | Z22: वेळापत्रक | AH22: वेळापत्रक | AP22: वेळापत्रक
B23: इयत्ताः- पाचवी तुकडीः- ब वर्गशिक्षकः- श्री.बोडखे रमेश साहेबराव | J23: इयत्ताः- सहावी तुकडीः- ब वर्गशिक्षकः- श्री.सानप बाळासाहेब दगु | R23: इयत्ताः- सातवी तुकडीः- ब वर्गशिक्षकः- श्री.ठोंबरे लक्ष्मण शंकर | Z23: इयत्ताः- आठवी तुकडीः- ब वर्गशिक्षकः- श्री.कुलकर्णी मंदार लक्ष्मीकांत | AH23: इयत्ताः- नववी तुकडीः- ब वर्गशिक्षकः- श्री.सानप गोकुळ बबन | AP23: इयत्ताः- दहावी तुकडीः- ब वर्गशिक्षकः- श्री.गडाख शरद सुधाकर
B24: अ.नं. | C24: सोमवार | D24: मंगळवार | E24: बुधवार | F24: गुरूवार | G24: शुक्रवार | H24: शनिवार | J24: अ.नं. | K24: सोमवार | L24: मंगळवार | M24: बुधवार | N24: गुरूवार | O24: शुक्रवार | P24: शनिवार | R24: अ.नं. | S24: सोमवार | T24: मंगळवार | U24: बुधवार | V24: गुरूवार | W24: शुक्रवार | X24: शनिवार | Z24: अ.नं. | AA24: सोमवार | AB24: मंगळवार | AC24: बुधवार | AD24: गुरूवार | AE24: शुक्रवार | AF24: शनिवार | AH24: अ.नं. | AI24: सोमवार | AJ24: मंगळवार | AK24: बुधवार | AL24: गुरूवार | AM24: शुक्रवार | AN24: शनिवार | AP24: अ.नं. | AQ24: सोमवार | AR24: मंगळवार | AS24: बुधवार | AT24: गुरूवार | AU24: शुक्रवार | AV24: शनिवार
B25: 1 | C25: गणित | D25: गणित | E25: गणित | F25: गणित | G25: गणित | H25: गणित | J25: 1 | K25: मराठी | L25: मराठी | M25: मराठी | N25: मराठी | O25: मराठी | P25: मराठी | R25: 1 | S25: समाजशास्त्र | T25: समाजशास्त्र | U25: समाजशास्त्र | V25: समाजशास्त्र | W25: समाजशास्त्र | X25: समाजशास्त्र | Z25: 1 | AA25: गणित | AB25: गणित | AC25: गणित | AD25: गणित | AE25: गणित | AF25: गणित | AH25: 1 | AI25: मराठी | AJ25: मराठी | AK25: मराठी | AL25: मराठी | AM25: मराठी | AN25: मराठी | AP25: 1 | AQ25: गणित | AR25: गणित | AS25: गणित | AT25: गणित | AU25: गणित | AV25: गणित
C26: बोडखे आर.एस. | D26: बोडखे आर.एस. | E26: बोडखे आर.एस. | F26: बोडखे आर.एस. | G26: बोडखे आर.एस. | H26: बोडखे आर.एस. | K26: सानप बी.डी. | L26: सानप बी.डी. | M26: सानप बी.डी. | N26: सानप बी.डी. | O26: सानप बी.डी. | P26: सानप बी.डी. | S26: ठोंबरे एल.एस. | T26: ठोंबरे एल.एस. | U26: ठोंबरे एल.एस. | V26: ठोंबरे एल.एस. | W26: ठोंबरे एल.एस. | X26: ठोंबरे एल.एस. | AA26: कुलकर्णी एम.एल. | AB26: कुलकर्णी एम.एल. | AC26: कुलकर्णी एम.एल. | AD26: कुलकर्णी एम.एल. | AE26: कुलकर्णी एम.एल. | AF26: कुलकर्णी एम.एल. | AI26: सानप जी.बी. | AJ26: सानप जी.बी. | AK26: सानप जी.बी. | AL26: सानप जी.बी. | AM26: सानप जी.बी. | AN26: सानप जी.बी. | AQ26: गडाख एस.एस. | AR26: गडाख एस.एस. | AS26: गडाख एस.एस. | AT26: गडाख एस.एस. | AU26: गडाख एस.एस. | AV26: गडाख एस.एस.
B27: 2 | C27: कार्यशिक्षण | D27: कार्यशिक्षण | E27: कार्यशिक्षण | F27: शा,शिक्षण | G27: परिसर 1 | H27: परिसर 1 | J27: 2 | K27: इंग्रजी | L27: इंग्रजी | M27: इंग्रजी | N27: इंग्रजी | O27: इंग्रजी | P27: इंग्रजी | R27: 2 | S27: हिंदी | T27: हिंदी | U27: हिंदी | V27: हिंदी | W27: कार्यशिक्षण | X27: कार्यशिक्षण | Z27: 2 | AA27: मराठी | AB27: मराठी | AC27: मराठी | AD27: मराठी | AE27: मराठी | AF27: मराठी | AH27: 2 | AI27: इंग्रजी | AJ27: इंग्रजी | AK27: इंग्रजी | AL27: इंग्रजी | AM27: इंग्रजी | AN27: इंग्रजी | AP27: 2 | AQ27: मराठी | AR27: मराठी | AS27: मराठी | AT27: मराठी | AU27: मराठी | AV27: मराठी
C28: गिते एस.एस. | D28: गिते एस.एस. | E28: गिते एस.एस. | F28: वाघ व्ही.व्ही. | G28: सानप बी.डी. | H28: सानप बी.डी. | K28: चौधरी एस.बी. | L28: चौधरी एस.बी. | M28: चौधरी एस.बी. | N28: चौधरी एस.बी. | O28: चौधरी एस.बी. | P28: चौधरी एस.बी. | S28: दराडे एस.एल. | T28: दराडे एस.एल. | U28: दराडे एस.एल. | V28: दराडे एस.एल. | W28: गिते एस.एस. | X28: गिते एस.एस. | AA28: पानसरे व्ही.व्ही. | AB28: पानसरे व्ही.व्ही. | AC28: पानसरे व्ही.व्ही. | AD28: पानसरे व्ही.व्ही. | AE28: पानसरे व्ही.व्ही. | AF28: पानसरे व्ही.व्ही. | AI28: घुगे एस.आर. | AJ28: घुगे एस.आर. | AK28: घुगे एस.आर. | AL28: घुगे एस.आर. | AM28: घुगे एस.आर. | AN28: घुगे एस.आर. | AQ28: ठोंबरे एस.एल. | AR28: ठोंबरे एस.एल. | AS28: ठोंबरे एस.एल. | AT28: ठोंबरे एस.एल. | AU28: ठोंबरे एस.एल. | AV28: ठोंबरे एस.एल.
B29: 3 | C29: परिसर 1 | D29: परिसर 1 | E29: परिसर 1 | F29: परिसर 1 | G29: इंग्रजी | H29: शा,शिक्षण | J29: 3 | K29: कला | L29: कला | M29: कला | N29: समाजशास्त्र | O29: हिंदी | P29: समाजशास्त्र | R29: 3 | S29: गणित | T29: गणित | U29: गणित | V29: गणित | W29: गणित | X29: गणित | Z29: 3 | AA29: समाजशास्त्र | AB29: समाजशास्त्र | AC29: समाजशास्त्र | AD29: समाजशास्त्र | AE29: समाजशास्त्र | AF29: शा.शिक्षण | AH29: 3 | AI29: गणित | AJ29: गणित | AK29: गणित | AL29: गणित | AM29: गणित | AN29: गणित | AP29: 3 | AQ29: इंग्रजी | AR29: इंग्रजी | AS29: इंग्रजी | AT29: इंग्रजी | AU29: इंग्रजी | AV29: इंग्रजी
C30: सानप बी.डी. | D30: सानप बी.डी. | E30: सानप बी.डी. | F30: सानप बी.डी. | G30: चौधरी एस.बी. | H30: वाघ व्ही.व्ही. | K30: वाघ एस.एन. | L30: वाघ एस.एन. | M30: वाघ एस.एन. | N30: चौधरी एस.बी. | O30: ठोंबरे एल.एस. | P30: चौधरी एस.बी. | S30: बोडखे आर.एस. | T30: बोडखे आर.एस. | U30: बोडखे आर.एस. | V30: बोडखे आर.एस. | W30: बोडखे आर.एस. | X30: बोडखे आर.एस. | AA30: काकड आर.बी. | AB30: काकड आर.बी. | AC30: काकड आर.बी. | AD30: काकड आर.बी. | AE30: काकड आर.बी. | AF30: वाघ आर.बी. | AI30: कुलकर्णी एम.एल. | AJ30: कुलकर्णी एम.एल. | AK30: कुलकर्णी एम.एल. | AL30: कुलकर्णी एम.एल. | AM30: कुलकर्णी एम.एल. | AN30: कुलकर्णी एम.एल. | AQ30: जगताप एस.डी. | AR30: जगताप एस.डी. | AS30: जगताप एस.डी. | AT30: जगताप एस.डी. | AU30: जगताप एस.डी. | AV30: जगताप एस.डी.
B31: 4 | C31: इंग्रजी | D31: इंग्रजी | E31: इंग्रजी | F31: इंग्रजी | G31: कला | H31: कला | J31: 4 | K31: गणित | L31: गणित | M31: गणित | N31: गणित | O31: गणित | P31: गणित | R31: 4 | S31: मराठी | T31: मराठी | U31: मराठी | V31: मराठी | W31: मराठी | X31: मराठी | Z31: 4 | AA31: विज्ञान | AB31: विज्ञान | AC31: विज्ञान | AD31: विज्ञान | AE31: विज्ञान | AF31: विज्ञान | AH31: 4 | AI31: इतिहास | AJ31: इतिहास | AK31: इतिहास | AL31: इतिहास | AM31: स्का./गाईड | AN31: स्का./गाईड | AP31: 4 | AQ31: हिंदी | AR31: हिंदी | AS31: हिंदी | AT31: हिंदी | AU31: हिंदी | AV31: हिंदी
C32: चौधरी एस.बी. | D32: चौधरी एस.बी. | E32: चौधरी एस.बी. | F32: चौधरी एस.बी. | G32: वाघ एस.एन. | H32: वाघ एस.एन. | K32: बोडके आर.एस. | L32: बोडके आर.एस. | M32: बोडके आर.एस. | N32: बोडके आर.एस. | O32: बोडके आर.एस. | P32: बोडके आर.एस. | S32: सानप जी.बी. | T32: सानप जी.बी. | U32: सानप जी.बी. | V32: सानप जी.बी. | W32: सानप जी.बी. | X32: सानप जी.बी. | AA32: कुलकर्णी एम.एल. | AB32: कुलकर्णी एम.एल. | AC32: कुलकर्णी एम.एल. | AD32: कुलकर्णी एम.एल. | AE32: कुलकर्णी एम.एल. | AF32: कुलकर्णी एम.एल. | AI32: ठोंबरे एस.एल. | AJ32: ठोंबरे एस.एल. | AK32: ठोंबरे एस.एल. | AL32: ठोंबरे एस.एल. | AM32: चौधरी एस.बी. | AN32: चौधरी एस.बी. | AQ32: वाघ व्ही.व्ही. | AR32: वाघ व्ही.व्ही. | AS32: वाघ व्ही.व्ही. | AT32: वाघ व्ही.व्ही. | AU32: वाघ व्ही.व्ही. | AV32: वाघ व्ही.व्ही.
B33: ********* मधली सुट्टी ********* | J33: ********* मधली सुट्टी ********* | R33: ********* मधली सुट्टी ********* | Z33: ********* मधली सुट्टी ********* | AH33: ********* मधली सुट्टी ********* | AP33: ********* मधली सुट्टी *********
B34: 5 | C34: मराठी | D34: मराठी | E34: मराठी | F34: मराठी | G34: मराठी | H34: इंग्रजी | J34: 5 | K34: विज्ञान | L34: विज्ञान | M34: विज्ञान | N34: विज्ञान | O34: विज्ञान | P34: गणित | R34: 5 | S34: कला | T34: कला | U34: कला | V34: कला | W34: इंग्रजी | X34: विज्ञान | Z34: 5 | AA34: हिंदी | AB34: हिंदी | AC34: हिंदी | AD34: हिंदी | AE34: हिंदी | AF34: हिंदी | AH34: 5 | AI34: हिंदी | AJ34: हिंदी | AK34: हिंदी | AL34: हिंदी | AM34: हिंदी | AN34: इंग्रजी | AP34: 5 | AQ34: इतिहास | AR34: इतिहास | AS34: इतिहास | AT34: इतिहास | AU34: विज्ञान | AV34: विज्ञान
C35: सानप जी.बी. | D35: सानप जी.बी. | E35: सानप जी.बी. | F35: सानप जी.बी. | G35: सानप जी.बी. | H35: चौधरी एस.बी. | K35: बोडके आर.एस. | L35: बोडके आर.एस. | M35: बोडके आर.एस. | N35: बोडके आर.एस. | O35: बोडके आर.एस. | P35: बोडके आर.एस. | S35: वाघ एस.एन. | T35: वाघ एस.एन. | U35: वाघ एस.एन. | V35: वाघ एस.एन. | W35: चौधरी एस.बी. | X35: गिते जे.ए. | AA35: ठोंबरे एल.एस. | AB35: ठोंबरे एल.एस. | AC35: ठोंबरे एल.एस. | AD35: ठोंबरे एल.एस. | AE35: ठोंबरे एल.एस. | AF35: ठोंबरे एल.एस. | AI35: दराडे एस.एल. | AJ35: दराडे एस.एल. | AK35: दराडे एस.एल. | AL35: दराडे एस.एल. | AM35: दराडे एस.एल. | AN35: घुगे एस.आर. | AQ35: काकड आर.बी. | AR35: काकड आर.बी. | AS35: काकड आर.बी. | AT35: काकड आर.बी. | AU35: कुलकर्णी एम.एल. | AV35: कुलकर्णी एम.एल.
B36: 6 | C36: हिंदी | D36: हिंदी | E36: हिंदी | F36: हिंदी | G36: कला | H36: मराठी | J36: 6 | K36: शा.शिक्षण | L36: शा.शिक्षण | M36: शा.शिक्षण | N36: शा.शिक्षण | O36: विज्ञान | P36: कार्यशिक्षण | R36: 6 | S36: विज्ञान | T36: विज्ञान | U36: विज्ञान | V36: विज्ञान | W36: विज्ञान | X36: गणित | Z36: 6 | AA36: इंग्रजी | AB36: इंग्रजी | AC36: इंग्रजी | AD36: इंग्रजी | AE36: इंग्रजी | AF36: इंग्रजी | AH36: 6 | AI36: भूगोल | AJ36: भूगोल | AK36: जलसुरक्षा | AL36: जलसुरक्षा | AM36: भूगोल | AN36: गणित | AP36: 6 | AQ36: विज्ञान | AR36: विज्ञान | AS36: विज्ञान | AT36: विज्ञान | AU36: विज्ञान | AV36: शा.शिक्षण
C37: बोडखे आर.एस. | D37: बोडखे आर.एस. | E37: बोडखे आर.एस. | F37: बोडखे आर.एस. | G37: वाघ एस.एन. | H37: सानप जी.बी. | K37: वाघ आर.बी. | L37: वाघ आर.बी. | M37: वाघ आर.बी. | N37: वाघ आर.बी. | O37: बोडके आर.एस. | P37: घुगे एस.आर. | S37: गिते जे.ए. | T37: गिते जे.ए. | U37: गिते जे.ए. | V37: गिते जे.ए. | W37: गिते जे.ए. | X37: बोडखे आर.एस. | AA37: जगताप एस.डी. | AB37: जगताप एस.डी. | AC37: जगताप एस.डी. | AD37: जगताप एस.डी. | AE37: जगताप एस.डी. | AF37: जगताप एस.डी. | AI37: पानसरे व्ही.व्ही. | AJ37: पानसरे व्ही.व्ही. | AK37: घुगे एस.आर. | AL37: घुगे एस.आर. | AM37: पानसरे व्ही.व्ही. | AN37: कुलकर्णी एम.एल. | AQ37: कुलकर्णी एम.एल. | AR37: कुलकर्णी एम.एल. | AS37: कुलकर्णी एम.एल. | AT37: कुलकर्णी एम.एल. | AU37: कुलकर्णी एम.एल. | AV37: वाघ आर.बी.
B38: 7 | C38: परिसर 2 | D38: परिसर 2 | E38: परिसर 2 | F38: परिसर 2 | G38: शा,शिक्षण | H38: परिसर 2 | J38: 7 | K38: हिंदी | L38: हिंदी | M38: हिंदी | N38: हिंदी | O38: कार्यशिक्षण | P38: कला | R38: 7 | S38: इंग्रजी | T38: इंग्रजी | U38: इंग्रजी | V38: इंग्रजी | W38: विज्ञान | X38: इंग्रजी | Z38: 7 | AA38: शा.शिक्षण | AB38: कला | AC38: कला | AD38: कला | AE38: कला | AF38: समाजशास्त्र | AH38: 7 | AI38: विज्ञान | AJ38: विज्ञान | AK38: विज्ञान | AL38: विज्ञान | AM38: विज्ञान | AN38: हिंदी | AP38: 7 | AQ38: भूगोल | AR38: भूगोल | AS38: भूगोल | AT38: शा.शिक्षण | AU38: इंग्रजी | AV38: गणित
C39: सानप बी.डी. | D39: सानप बी.डी. | E39: सानप बी.डी. | F39: सानप बी.डी. | G39: वाघ व्ही.व्ही. | H39: सानप बी.डी. | K39: ठोंबरे एल.एस. | L39: ठोंबरे एल.एस. | M39: ठोंबरे एल.एस. | N39: ठोंबरे एल.एस. | O39: घुगे एस.आर. | P39: वाघ एस.एन. | S39: चौधरी एस.बी. | T39: चौधरी एस.बी. | U39: चौधरी एस.बी. | V39: चौधरी एस.बी. | W39: गिते जे.ए. | X39: चौधरी एस.बी. | AA39: वाघ आर.बी. | AB39: वाघ एस.एन. | AC39: वाघ एस.एन. | AD39: वाघ एस.एन. | AE39: वाघ एस.एन. | AF39: काकड आर.बी. | AI39: कुलकर्णी एम.एल. | AJ39: कुलकर्णी एम.एल. | AK39: कुलकर्णी एम.एल. | AL39: कुलकर्णी एम.एल. | AM39: कुलकर्णी एम.एल. | AN39: दराडे एस.एल. | AQ39: पानसरे व्ही.व्ही. | AR39: पानसरे व्ही.व्ही. | AS39: पानसरे व्ही.व्ही. | AT39: वाघ आर.बी. | AU39: जगताप एस.डी. | AV39: गडाख एस.एस.
B40: 8 | C40: परिसर 2 | D40: गणित | E40: गणित | F40: हिंदी | G40: हिंदी | H40: शा,शिक्षण | J40: 8 | K40: समाजशास्त्र | L40: समाजशास्त्र | M40: समाजशास्त्र | N40: समाजशास्त्र | O40: हिंदी | P40: विज्ञान | R40: 8 | S40: शा.शिक्षण | T40: हिंदी | U40: हिंदी | V40: शा.शिक्षण | W40: शा.शिक्षण | X40: शा.शिक्षण | Z40: 8 | AA40: गणित | AB40: कार्यशिक्षण | AC40: कार्यशिक्षण | AD40: शा.शिक्षण | AE40: शा.शिक्षण | AF40: विज्ञान | AH40: 8 | AI40: शा.शिक्षण | AJ40: शा.शिक्षण | AK40: शा.शिक्षण | AL40: विज्ञान | AM40: विज्ञान | AN40: जलसुरक्षा | AP40: 8 | AQ40: जलसुरक्षा | AR40: स्का./गाईड | AS40: स्का./गाईड | AT40: जलसुरक्षा | AU40: जलसुरक्षा | AV40: शा.शिक्षण
C41: सानप बी.डी. | D41: बोडखे आर.एस. | E41: बोडखे आर.एस. | F41: बोडखे आर.एस. | G41: बोडखे आर.एस. | H41: वाघ व्ही.व्ही. | K41: चौधरी एस.बी. | L41: चौधरी एस.बी. | M41: चौधरी एस.बी. | N41: चौधरी एस.बी. | O41: ठोंबरे एल.एस. | P41: बोडके आर.एस. | S41: गिते एस.एस. | T41: दराडे एस.एल. | U41: दराडे एस.एल. | V41: गिते एस.एस. | W41: गिते एस.एस. | X41: गिते एस.एस. | AA41: कुलकर्णी एम.एल. | AB41: गिते एस.एस. | AC41: गिते एस.एस. | AD41: वाघ आर.बी. | AE41: वाघ आर.बी. | AF41: कुलकर्णी एम.एल. | AI41: वाघ व्ही.व्ही. | AJ41: वाघ व्ही.व्ही. | AK41: वाघ व्ही.व्ही. | AL41: कुलकर्णी एम.एल. | AM41: कुलकर्णी एम.एल. | AN41: घुगे एस.आर. | AQ41: जगताप एस.डी. | AR41: ठोंबरे एस.एल. | AS41: ठोंबरे एस.एल. | AT41: जगताप एस.डी. | AU41: जगताप एस.डी. | AV41: वाघ आर.बी.

Sheet शिक्षक वेळापत्रक
B1: वेळापत्रक | J1: वेळापत्रक | R1: वेळापत्रक | Z1: वेळापत्रक | AH1: वेळापत्रक | AP1: वेळापत्रक | AX1: वेळापत्रक | BF1: वेळापत्रक | BN1: वेळापत्रक
B2: श्री.संजय शिवाजी गिते ( प्राचार्य ) | J2: श्री.वाघ सुहास नारायण ( उपशिक्षक ) | R2: श्री.काकड रमेश भागवत ( उपशिक्षक ) | Z2: श्री.घुगे साहेबराव रामदास ( उपशिक्षक ) | AH2: श्री.ठोंबरे लक्ष्मण शंकर ( उपशिक्षक ) | AP2: श्री.गडाख शरद सुधाकर ( उपशिक्षक ) | AX2: श्रीम.गिते ज्योती अशोक ( उपशिक्षिका ) | BF2: श्री.दराडे सुनिल लक्ष्मण ( उपशिक्षक ) | BN2: श्री.बोडखे रमेश साहेबराव ( उपशिक्षक )
B3: अ.नं. | C3: सोमवार | D3: मंगळवार | E3: बुधवार | F3: गुरूवार | G3: शुक्रवार | H3: शनिवार | J3: अ.नं. | K3: सोमवार | L3: मंगळवार | M3: बुधवार | N3: गुरूवार | O3: शुक्रवार | P3: शनिवार | R3: अ.नं. | S3: सोमवार | T3: मंगळवार | U3: बुधवार | V3: गुरूवार | W3: शुक्रवार | X3: शनिवार | Z3: अ.नं. | AA3: सोमवार | AB3: मंगळवार | AC3: बुधवार | AD3: गुरूवार | AE3: शुक्रवार | AF3: शनिवार | AH3: अ.नं. | AI3: सोमवार | AJ3: मंगळवार | AK3: बुधवार | AL3: गुरूवार | AM3: शुक्रवार | AN3: शनिवार | AP3: अ.नं. | AQ3: सोमवार | AR3: मंगळवार | AS3: बुधवार | AT3: गुरूवार | AU3: शुक्रवार | AV3: शनिवार | AX3: अ.नं. | AY3: सोमवार | AZ3: मंगळवार | BA3: बुधवार | BB3: गुरूवार | BC3: शुक्रवार | BD3: शनिवार | BF3: अ.नं. | BG3: सोमवार | BH3: मंगळवार | BI3: बुधवार | BJ3: गुरूवार | BK3: शुक्रवार | BL3: शनिवार | BN3: अ.नं. | BO3: सोमवार | BP3: मंगळवार | BQ3: बुधवार | BR3: गुरूवार | BS3: शुक्रवार | BT3: शनिवार
B4: 1 | J4: 1 | R4: 1 | S4: मराठी | T4: मराठी | U4: मराठी | V4: मराठी | W4: मराठी | X4: मराठी | Z4: 1 | AH4: 1 | AI4: समाजशास्त्र | AJ4: समाजशास्त्र | AK4: समाजशास्त्र | AL4: समाजशास्त्र | AM4: समाजशास्त्र | AN4: समाजशास्त्र | AP4: 1 | AQ4: गणित | AR4: गणित | AS4: गणित | AT4: गणित | AU4: गणित | AV4: गणित | AX4: 1 | AY4: गणित | AZ4: गणित | BA4: गणित | BB4: गणित | BC4: गणित | BD4: गणित | BF4: 1 | BG4: हिंदी | BH4: हिंदी | BI4: हिंदी | BJ4: हिंदी | BK4: हिंदी | BL4: हिंदी | BN4: 1 | BO4: गणित | BP4: गणित | BQ4: गणित | BR4: गणित | BS4: गणित | BT4: गणित
S5: 9 वी अ | T5: 9 वी अ | U5: 9 वी अ | V5: 9 वी अ | W5: 9 वी अ | X5: 9 वी अ | AI5: 7 वी ब | AJ5: 7 वी ब | AK5: 7 वी ब | AL5: 7 वी ब | AM5: 7 वी ब | AN5: 7 वी ब | AQ5: 10 वी ब | AR5: 10 वी ब | AS5: 10 वी ब | AT5: 10 वी ब | AU5: 10 वी ब | AV5: 10 वी ब | AY5: 7 वी अ | AZ5: 7 वी अ | BA5: 7 वी अ | BB5: 7 वी अ | BC5: 7 वी अ | BD5: 7 वी अ | BG5: 6 वी अ | BH5: 6 वी अ | BI5: 6 वी अ | BJ5: 6 वी अ | BK5: 6 वी अ | BL5: 6 वी अ | BO5: 5 वी ब | BP5: 5 वी ब | BQ5: 5 वी ब | BR5: 5 वी ब | BS5: 5 वी ब | BT5: 5 वी ब
B6: 2 | C6: कार्यशिक्षण | D6: कार्यशिक्षण | E6: कार्यशिक्षण | G6: कार्यशिक्षण | H6: कार्यशिक्षण | J6: 2 | K6: कला | L6: कला | M6: कला | N6: कला | O6: कला | P6: कला | R6: 2 | S6: मराठी | T6: मराठी | U6: मराठी | V6: मराठी | Z6: 2 | AA6: इंग्रजी | AB6: इंग्रजी | AC6: इंग्रजी | AD6: इंग्रजी | AE6: इंग्रजी | AF6: इंग्रजी | AH6: 2 | AI6: मराठी | AJ6: मराठी | AK6: मराठी | AL6: मराठी | AM6: मराठी | AN6: मराठी | AP6: 2 | AQ6: गणित | AR6: गणित | AS6: गणित | AT6: गणित | AU6: गणित | AV6: गणित | AX6: 2 | AY6: गणित | AZ6: गणित | BA6: गणित | BB6: गणित | BC6: गणित | BD6: गणित | BF6: 2 | BG6: हिंदी | BH6: हिंदी | BI6: हिंदी | BJ6: हिंदी | BN6: 2
C7: 5 वी ब | D7: 5 वी ब | E7: 5 वी ब | G7: 7 वी ब | H7: 7 वी ब | K7: 7 वी अ | L7: 7 वी अ | M7: 7 वी अ | N7: 7 वी अ | O7: 6 वी अ | P7: 6 वी अ | S7: 6 वी अ | T7: 6 वी अ | U7: 6 वी अ | V7: 6 वी अ | AA7: 9 वी ब | AB7: 9 वी ब | AC7: 9 वी ब | AD7: 9 वी ब | AE7: 9 वी ब | AF7: 9 वी ब | AI7: 10 वी ब | AJ7: 10 वी ब | AK7: 10 वी ब | AL7: 10 वी ब | AM7: 10 वी ब | AN7: 10 वी ब | AQ7: 10 वी अ | AR7: 10 वी अ | AS7: 10 वी अ | AT7: 10 वी अ | AU7: 10 वी अ | AV7: 10 वी अ | AY7: 8 वी अ | AZ7: 8 वी अ | BA7: 8 वी अ | BB7: 8 वी अ | BC7: 8 वी अ | BD7: 8 वी अ | BG7: 7 वी ब | BH7: 7 वी ब | BI7: 7 वी ब | BJ7: 7 वी ब
B8: 3 | J8: 3 | K8: कला | L8: कला | M8: कला | R8: 3 | S8: समाजशास्त्र | T8: समाजशास्त्र | U8: समाजशास्त्र | V8: समाजशास्त्र | W8: समाजशास्त्र | Z8: 3 | AA8: इंग्रजी | AB8: इंग्रजी | AC8: इंग्रजी | AD8: इंग्रजी | AE8: इंग्रजी | AF8: इंग्रजी | AH8: 3 | AM8: हिंदी | AN8: कार्यशिक्षण | AP8: 3 | AX8: 3 | BD8: गणित | BF8: 3 | BN8: 3 | BO8: गणित | BP8: गणित | BQ8: गणित | BR8: गणित | BS8: गणित | BT8: गणित
K9: 6 वी ब | L9: 6 वी ब | M9: 6 वी ब | S9: 8 वी ब | T9: 8 वी ब | U9: 8 वी ब | V9: 8 वी ब | W9: 8 वी ब | AA9: 10 वी अ | AB9: 10 वी अ | AC9: 10 वी अ | AD9: 10 वी अ | AE9: 10 वी अ | AF9: 10 वी अ | AM9: 6 वी ब | AN9: 7 वी अ | BD9: 9 वी अ | BO9: 7 वी ब | BP9: 7 वी ब | BQ9: 7 वी ब | BR9: 7 वी ब | BS9: 7 वी ब | BT9: 7 वी ब
B10: 4 | J10: 4 | K10: कला | L10: कला | O10: कला | P10: कला | R10: 4 | Z10: 4 | AA10: इंग्रजी | AB10: इंग्रजी | AC10: इंग्रजी | AD10: इंग्रजी | AE10: इंग्रजी | AF10: इंग्रजी | AH10: 4 | AI10: इतिहास | AJ10: इतिहास | AK10: इतिहास | AL10: इतिहास | AP10: 4 | AQ10: विज्ञान | AR10: विज्ञान | AS10: विज्ञान | AT10: विज्ञान | AU10: विज्ञान | AV10: विज्ञान | AX10: 4 | AY10: गणित | AZ10: गणित | BA10: गणित | BB10: गणित | BC10: गणित | BD10: गणित | BF10: 4 | BG10: हिंदी | BH10: हिंदी | BI10: हिंदी | BJ10: हिंदी | BK10: हिंदी | BL10: हिंदी | BN10: 4 | BO10: गणित | BP10: गणित | BQ10: गणित | BR10: गणित | BS10: गणित | BT10: गणित
K11: 6 वी अ | L11: 6 वी अ | O11: 5 वी ब | P11: 5 वी ब | AA11: 7 वी अ | AB11: 7 वी अ | AC11: 7 वी अ | AD11: 7 वी अ | AE11: 7 वी अ | AF11: 7 वी अ | AI11: 9 वी ब | AJ11: 9 वी ब | AK11: 9 वी ब | AL11: 9 वी ब | AQ11: 8 वी अ | AR11: 8 वी अ | AS11: 8 वी अ | AT11: 8 वी अ | AU11: 8 वी अ | AV11: 8 वी अ | AY11: 9 वी अ | AZ11: 9 वी अ | BA11: 9 वी अ | BB11: 9 वी अ | BC11: 9 वी अ | BD11: 9 वी अ | BG11: 10 वी अ | BH11: 10 वी अ | BI11: 10 वी अ | BJ11: 10 वी अ | BK11: 10 वी अ | BL11: 10 वी अ | BO11: 6 वी ब | BP11: 6 वी ब | BQ11: 6 वी ब | BR11: 6 वी ब | BS11: 6 वी ब | BT11: 6 वी ब
B12: ********* मधली सुट्टी ********* | J12: ********* मधली सुट्टी ********* | R12: ********* मधली सुट्टी ********* | Z12: ********* मधली सुट्टी ********* | AH12: ********* मधली सुट्टी ********* | AP12: ********* मधली सुट्टी ********* | AX12: ********* मधली सुट्टी ********* | BF12: ********* मधली सुट्टी ********* | BN12: ********* मधली सुट्टी *********
B13: 5 | J13: 5 | K13: कला | L13: कला | M13: कला | N13: कला | P13: कला | R13: 5 | S13: इतिहास | T13: इतिहास | U13: इतिहास | V13: इतिहास | W13: समाजशास्त्र | X13: समाजशास्त्र | Z13: 5 | AA13: इंग्रजी | AB13: इंग्रजी | AC13: इंग्रजी | AD13: इंग्रजी | AE13: इंग्रजी | AF13: इंग्रजी | AH13: 5 | AI13: हिंदी | AJ13: हिंदी | AK13: हिंदी | AL13: हिंदी | AM13: हिंदी | AN13: हिंदी | AP13: 5 | AQ13: विज्ञान | AR13: विज्ञान | AV13: गणित | AX13: 5 | AY13: विज्ञान | AZ13: विज्ञान | BA13: विज्ञान | BB13: विज्ञान | BC13: विज्ञान | BD13: विज्ञान | BF13: 5 | BG13: हिंदी | BH13: हिंदी | BI13: हिंदी | BJ13: हिंदी | BK13: हिंदी | BN13: 5 | BO13: विज्ञान | BP13: विज्ञान | BQ13: विज्ञान | BR13: विज्ञान | BS13: विज्ञान | BT13: गणित
K14: 7 वी ब | L14: 7 वी ब | M14: 7 वी ब | N14: 7 वी ब | P14: 5 वी अ | S14: 10 वी ब | T14: 10 वी ब | U14: 10 वी ब | V14: 10 वी ब | W14: 8 वी अ | X14: 8 वी अ | AA14: 6 वी अ | AB14: 6 वी अ | AC14: 6 वी अ | AD14: 6 वी अ | AE14: 6 वी अ | AF14: 9 वी ब | AI14: 8 वी ब | AJ14: 8 वी ब | AK14: 8 वी ब | AL14: 8 वी ब | AM14: 8 वी ब | AN14: 8 वी ब | AQ14: 9 वी अ | AR14: 9 वी अ | AV14: 10 वी अ | AY14: 10 वी अ | AZ14: 10 वी अ | BA14: 10 वी अ | BB14: 10 वी अ | BC14: 10 वी अ | BD14: 7 वी ब | BG14: 9 वी ब | BH14: 9 वी ब | BI14: 9 वी ब | BJ14: 9 वी ब | BK14: 9 वी ब | BO14: 6 वी ब | BP14: 6 वी ब | BQ14: 6 वी ब | BR14: 6 वी ब | BS14: 6 वी ब | BT14: 6 वी ब
B15: 6 | H15: स्का./गाईड | J15: 6 | O15: कला | P15: कला | R15: 6 | S15: इतिहास | T15: इतिहास | U15: इतिहास | V15: इतिहास | W15: मराठी | X15: मराठी | Z15: 6 | AC15: जलसुरक्षा | AD15: जलसुरक्षा | AF15: कार्यशिक्षण | AH15: 6 | AM15: स्का. / गाईड | AN15: कार्यशिक्षण | AP15: 6 | AQ15: विज्ञान | AR15: विज्ञान | AS15: विज्ञान | AT15: विज्ञान | AU15: विज्ञान | AX15: 6 | AY15: विज्ञान | AZ15: विज्ञान | BA15: विज्ञान | BB15: विज्ञान | BC15: विज्ञान | BF15: 6 | BG15: हिंदी | BH15: हिंदी | BI15: हिंदी | BJ15: हिंदी | BK15: हिंदी | BL15: हिंदी | BN15: 6 | BO15: हिंदी | BP15: हिंदी | BQ15: हिंदी | BR15: हिंदी | BS15: विज्ञान | BT15: गणित
H16: 9 वी अ | O16: 5 वी ब | P16: 5 वी अ | S16: 10 वी अ | T16: 10 वी अ | U16: 10 वी अ | V16: 10 वी अ | W16: 6 वी अ | X16: 6 वी अ | AC16: 9 वी ब | AD16: 9 वी ब | AF16: 6 वी ब | AM16: 10 वी अ | AN16: 7 वी अ | AQ16: 7 वी अ | AR16: 7 वी अ | AS16: 7 वी अ | AT16: 7 वी अ | AU16: 7 वी अ | AY16: 7 वी ब | AZ16: 7 वी ब | BA16: 7 वी ब | BB16: 7 वी ब | BC16: 7 वी ब | BG16: 8 वी अ | BH16: 8 वी अ | BI16: 8 वी अ | BJ16: 8 वी अ | BK16: 8 वी अ | BL16: 8 वी अ | BO16: 5 वी ब | BP16: 5 वी ब | BQ16: 5 वी ब | BR16: 5 वी ब | BS16: 6 वी ब | BT16: 7 वी ब
B17: 7 | J17: 7 | K17: कला | L17: कला | M17: कला | N17: कला | O17: कला | P17: कला | R17: 7 | S17: समाजशास्त्र | T17: समाजशास्त्र | U17: समाजशास्त्र | V17: समाजशास्त्र | X17: समाजशास्त्र | Z17: 7 | AC17: इंग्रजी | AE17: कार्यशिक्षण | AH17: 7 | AI17: हिंदी | AJ17: हिंदी | AK17: हिंदी | AL17: हिंदी | AN17: स्का. / गाईड | AP17: 7 | AQ17: विज्ञान | AR17: विज्ञान | AS17: विज्ञान | AT17: विज्ञान | AU17: विज्ञान | AV17: गणित | AX17: 7 | AY17: गणित | AZ17: विज्ञान | BC17: विज्ञान | BD17: गणित | BF17: 7 | BG17: भूगोल | BJ17: भूगोल | BK17: भूगोल | BL17: हिंदी | BN17: 7
K18: 5 वी अ | L18: 8 वी ब | M18: 8 वी ब | N18: 8 वी ब | O18: 8 वी ब | P18: 6 वी ब | S18: 8 वी अ | T18: 8 वी अ | U18: 8 वी अ | V18: 8 वी अ | X18: 8 वी ब | AC18: 10 वी अ | AE18: 6 वी ब | AI18: 6 वी ब | AJ18: 6 वी ब | AK18: 6 वी ब | AL18: 6 वी ब | AN18: 10 वी अ | AQ18: 9 वी अ | AR18: 9 वी अ | AS18: 9 वी अ | AT18: 9 वी अ | AU18: 8 वी अ | AV18: 10 वी ब | AY18: 7 वी अ | AZ18: 10 वी अ | BC18: 7 वी ब | BD18: 8 वी अ | BG18: 10 वी अ | BJ18: 10 वी अ | BK18: 10 वी अ | BL18: 9 वी ब
B19: 8 | C19: शा.शिक्षण | D19: कार्यशिक्षण | E19: कार्यशिक्षण | F19: शा.शिक्षण | G19: शा.शिक्षण | H19: शा.शिक्षण | J19: 8 | K19: कार्यशिक्षण | L19: कला | M19: कला | N19: कला | O19: कला | P19: कार्यशिक्षण | R19: 8 | S19: कार्यशिक्षण | X19: कार्यशिक्षण | Z19: 8 | AA19: जलसुरक्षा | AB19: जलसुरक्षा | AC19: जलसुरक्षा | AD19: इंग्रजी | AF19: जलसुरक्षा | AH19: 8 | AJ19: स्का. / गाईड | AK19: स्का. / गाईड | AM19: हिंदी | AP19: 8 | AQ19: विज्ञान | AU19: विज्ञान | AV19: विज्ञान | AX19: 8 | BD19: विज्ञान | BF19: 8 | BH19: हिंदी | BI19: हिंदी | BN19: 8 | BP19: गणित | BQ19: गणित | BR19: हिंदी | BS19: हिंदी | BT19: विज्ञान
C20: 7 वी ब | D20: 8 वी ब | E20: 8 वी ब | F20: 7 वी ब | G20: 7 वी ब | H20: 7 वी ब | K20: 6 वी अ | L20: 8 वी अ | M20: 8 वी अ | N20: 8 वी अ | O20: 8 वी अ | P20: 6 वी अ | S20: 8 वी अ | X20: 8 वी अ | AA20: 10 वी अ | AB20: 10 वी अ | AC20: 10 वी अ | AD20: 6 वी अ | AF20: 9 वी ब | AJ20: 10 वी ब | AK20: 10 वी ब | AM20: 6 वी ब | AQ20: 7 वी अ | AU20: 9 वी अ | AV20: 7 वी अ | BD20: 10 वी अ | BH20: 7 वी ब | BI20: 7 वी ब | BP20: 5 वी ब | BQ20: 5 वी ब | BR20: 5 वी ब | BS20: 5 वी ब | BT20: 6 वी ब
B22: वेळापत्रक | J22: वेळापत्रक | R22: वेळापत्रक | Z22: वेळापत्रक | AH22: वेळापत्रक | AP22: वेळापत्रक | AX22: वेळापत्रक | BF22: वेळापत्रक | BN22: वेळापत्रक
B23: श्री.वाघ राजेंद्र भागचंद ( पर्यवेक्षक ) | J23: श्री.सानप बाळासाहेब दगु ( उपशिक्षक ) | R23: श्री.वाघ विलास वाळूबा ( उपशिक्षक ) | Z23: श्री.जगताप संदिप दादाजी ( उपशिक्षक ) | AH23: श्री.पानसरे वसंत वाल्मिक ( उपशिक्षक ) | AP23: श्री.कुलकर्णी मंदार लक्ष्मीकांत ( उपशिक्षक ) | AX23: श्री.सानप गोकुळ बबन ( उपशिक्षक ) | BF23: श्रीम.चौधरी शंकूतल बाबुराव ( उपशिक्षिका ) | BN23: श्री.दराडे ज्ञानेश्वर दत्तु ( उपशिक्षक )
B24: अ.नं. | C24: सोमवार | D24: मंगळवार | E24: बुधवार | F24: गुरूवार | G24: शुक्रवार | H24: शनिवार | J24: अ.नं. | K24: सोमवार | L24: मंगळवार | M24: बुधवार | N24: गुरूवार | O24: शुक्रवार | P24: शनिवार | R24: अ.नं. | S24: सोमवार | T24: मंगळवार | U24: बुधवार | V24: गुरूवार | W24: शुक्रवार | X24: शनिवार | Z24: अ.नं. | AA24: सोमवार | AB24: मंगळवार | AC24: बुधवार | AD24: गुरूवार | AE24: शुक्रवार | AF24: शनिवार | AH24: अ.नं. | AI24: सोमवार | AJ24: मंगळवार | AK24: बुधवार | AL24: गुरूवार | AM24: शुक्रवार | AN24: शनिवार | AP24: अ.नं. | AQ24: सोमवार | AR24: मंगळवार | AS24: बुधवार | AT24: गुरूवार | AU24: शुक्रवार | AV24: शनिवार | AX24: अ.नं. | AY24: सोमवार | AZ24: मंगळवार | BA24: बुधवार | BB24: गुरूवार | BC24: शुक्रवार | BD24: शनिवार | BF24: अ.नं. | BG24: सोमवार | BH24: मंगळवार | BI24: बुधवार | BJ24: गुरूवार | BK24: शुक्रवार | BL24: शनिवार | BN24: अ.नं. | BO24: सोमवार | BP24: मंगळवार | BQ24: बुधवार | BR24: गुरूवार | BS24: शुक्रवार | BT24: शनिवार
B25: 1 | J25: 1 | K25: मराठी | L25: मराठी | M25: मराठी | N25: मराठी | O25: मराठी | P25: मराठी | R25: 1 | Z25: 1 | AA25: इंग्रजी | AB25: इंग्रजी | AC25: इंग्रजी | AD25: इंग्रजी | AE25: इंग्रजी | AF25: इंग्रजी | AH25: 1 | AI25: मराठी | AJ25: मराठी | AK25: मराठी | AL25: मराठी | AM25: मराठी | AN25: मराठी | AP25: 1 | AQ25: गणित | AR25: गणित | AS25: गणित | AT25: गणित | AU25: गणित | AV25: गणित | AX25: 1 | AY25: मराठी | AZ25: मराठी | BA25: मराठी | BB25: मराठी | BC25: मराठी | BD25: मराठी | BF25: 1 | BN25: 1 | BO25: गणित | BP25: गणित | BQ25: गणित | BR25: गणित | BS25: गणित | BT25: गणित
K26: 6 वी ब | L26: 6 वी ब | M26: 6 वी ब | N26: 6 वी ब | O26: 6 वी ब | P26: 6 वी ब | AA26: 8 वी अ | AB26: 8 वी अ | AC26: 8 वी अ | AD26: 8 वी अ | AE26: 8 वी अ | AF26: 8 वी अ | AI26: 10 वी अ | AJ26: 10 वी अ | AK26: 10 वी अ | AL26: 10 वी अ | AM26: 10 वी अ | AN26: 10 वी अ | AQ26: 8 वी ब | AR26: 8 वी ब | AS26: 8 वी ब | AT26: 8 वी ब | AU26: 8 वी ब | AV26: 8 वी ब | AY26: 9 वी ब | AZ26: 9 वी ब | BA26: 9 वी ब | BB26: 9 वी ब | BC26: 9 वी ब | BD26: 9 वी ब | BO26: 5 वी अ | BP26: 5 वी अ | BQ26: 5 वी अ | BR26: 5 वी अ | BS26: 5 वी अ | BT26: 5 वी अ
B27: 2 | G27: शा.शिक्षण | H27: शा.शिक्षण | J27: 2 | K27: हिंदी | L27: हिंदी | M27: हिंदी | N27: हिंदी | O27: परिसर 1 | P27: परिसर 1 | R27: 2 | V27: शा.शिक्षण | W27: हिंदी | X27: हिंदी | Z27: 2 | AA27: इंग्रजी | AB27: इंग्रजी | AC27: इंग्रजी | AD27: इंग्रजी | AE27: इंग्रजी | AF27: इंग्रजी | AH27: 2 | AI27: मराठी | AJ27: मराठी | AK27: मराठी | AL27: मराठी | AM27: मराठी | AN27: मराठी | AP27: 2 | AX27: 2 | BF27: 2 | BG27: इंग्रजी | BH27: इंग्रजी | BI27: इंग्रजी | BJ27: इंग्रजी | BK27: इंग्रजी | BL27: इंग्रजी | BN27: 2
G28: 5 वी अ | H28: 5 वी अ | K28: 5 वी अ | L28: 5 वी अ | M28: 5 वी अ | N28: 5 वी अ | O28: 5 वी ब | P28: 5 वी ब | V28: 5 वी ब | W28: 7 वी अ | X28: 7 वी अ | AA28: 9 वी अ | AB28: 9 वी अ | AC28: 9 वी अ | AD28: 9 वी अ | AE28: 9 वी अ | AF28: 9 वी अ | AI28: 8 वी ब | AJ28: 8 वी ब | AK28: 8 वी ब | AL28: 8 वी ब | AM28: 8 वी ब | AN28: 8 वी ब | BG28: 6 वी ब | BH28: 6 वी ब | BI28: 6 वी ब | BJ28: 6 वी ब | BK28: 6 वी ब | BL28: 6 वी ब
B29: 3 | C29: हिंदी | D29: हिंदी | E29: हिंदी | F29: हिंदी | G29: हिंदी | H29: शा.शिक्षण | J29: 3 | K29: परिसर 1 | L29: परिसर 1 | M29: परिसर 1 | N29: परिसर 1 | R29: 3 | S29: हिंदी | T29: हिंदी | U29: हिंदी | V29: हिंदी | W29: शा.शिक्षण | X29: शा.शिक्षण | Z29: 3 | AA29: इंग्रजी | AB29: इंग्रजी | AC29: इंग्रजी | AD29: इंग्रजी | AE29: इंग्रजी | AF29: इंग्रजी | AH29: 3 | AI29: मराठी | AJ29: मराठी | AK29: मराठी | AL29: मराठी | AM29: मराठी | AN29: मराठी | AP29: 3 | AQ29: गणित | AR29: गणित | AS29: गणित | AT29: गणित | AU29: गणित | AV29: गणित | AX29: 3 | AY29: मराठी | AZ29: मराठी | BA29: मराठी | BB29: मराठी | BC29: मराठी | BD29: मराठी | BF29: 3 | BJ29: समाजशास्त्र | BK29: इंग्रजी | BL29: समाजशास्त्र | BN29: 3 | BO29: गणित | BP29: गणित | BQ29: गणित | BR29: गणित | BS29: गणित | BT29: गणित
C30: 9 वी अ | D30: 9 वी अ | E30: 9 वी अ | F30: 9 वी अ | G30: 9 वी अ | H30: 8 वी ब | K30: 5 वी ब | L30: 5 वी ब | M30: 5 वी ब | N30: 5 वी ब | S30: 7 वी अ | T30: 7 वी अ | U30: 7 वी अ | V30: 7 वी अ | W30: 7 वी अ | X30: 5 वी ब | AA30: 10 वी ब | AB30: 10 वी ब | AC30: 10 वी ब | AD30: 10 वी ब | AE30: 10 वी ब | AF30: 10 वी ब | AI30: 8 वी अ | AJ30: 8 वी अ | AK30: 8 वी अ | AL30: 8 वी अ | AM30: 8 वी अ | AN30: 8 वी अ | AQ30: 9 वी ब | AR30: 9 वी ब | AS30: 9 वी ब | AT30: 9 वी ब | AU30: 9 वी ब | AV30: 9 वी ब | AY30: 5 वी अ | AZ30: 5 वी अ | BA30: 5 वी अ | BB30: 5 वी अ | BC30: 5 वी अ | BD30: 5 वी अ | BJ30: 6 वी ब | BK30: 5 वी ब | BL30: 6 वी ब | BO30: 6 वी अ | BP30: 6 वी अ | BQ30: 6 वी अ | BR30: 6 वी अ | BS30: 6 वी अ | BT30: 6 वी अ
B31: 4 | J31: 4 | M31: समाजशास्त्र | N31: समाजशास्त्र | O31: समाजशास्त्र | P31: समाजशास्त्र | R31: 4 | S31: हिंदी | T31: हिंदी | U31: हिंदी | V31: हिंदी | W31: हिंदी | X31: हिंदी | Z31: 4 | AH31: 4 | AP31: 4 | AQ31: विज्ञान | AR31: विज्ञान | AS31: विज्ञान | AT31: विज्ञान | AU31: विज्ञान | AV31: विज्ञान | AX31: 4 | AY31: मराठी | AZ31: मराठी | BA31: मराठी | BB31: मराठी | BC31: मराठी | BD31: मराठी | BF31: 4 | BG31: इंग्रजी | BH31: इंग्रजी | BI31: इंग्रजी | BJ31: इंग्रजी | BK31: स्का./ गाईड | BL31: स्का./ गाईड | BN31: 4 | BO31: परिसर 1 | BP31: परिसर 1 | BQ31: परिसर 1 | BR31: परिसर 1 | BS31: परिसर 1 | BT31: परिसर 1
M32: 6 वी अ | N32: 6 वी अ | O32: 6 वी अ | P32: 6 वी अ | S32: 10 वी ब | T32: 10 वी ब | U32: 10 वी ब | V32: 10 वी ब | W32: 10 वी ब | X32: 10 वी ब | AQ32: 8 वी ब | AR32: 8 वी ब | AS32: 8 वी ब | AT32: 8 वी ब | AU32: 8 वी ब | AV32: 8 वी ब | AY32: 7 वी ब | AZ32: 7 वी ब | BA32: 7 वी ब | BB32: 7 वी ब | BC32: 7 वी ब | BD32: 7 वी ब | BG32: 5 वी ब | BH32: 5 वी ब | BI32: 5 वी ब | BJ32: 5 वी ब | BK32: 9 वी ब | BL32: 9 वी ब | BO32: 5 वी अ | BP32: 5 वी अ | BQ32: 5 वी अ | BR32: 5 वी अ | BS32: 5 वी अ | BT32: 5 वी अ
B33: ********* मधली सुट्टी ********* | J33: ********* मधली सुट्टी ********* | R33: ********* मधली सुट्टी ********* | Z33: ********* मधली सुट्टी ********* | AH33: ********* मधली सुट्टी ********* | AP33: ********* मधली सुट्टी ********* | AX33: ********* मधली सुट्टी ********* | BF33: ********* मधली सुट्टी ********* | BN33: ********* मधली सुट्टी *********
B34: 5 | J34: 5 | R34: 5 | S34: शा.शिक्षण | T34: शा.शिक्षण | U34: शा.शिक्षण | V34: शा.शिक्षण | X34: शा.शिक्षण | Z34: 5 | AC34: इतिहास | AD34: इतिहास | AE34: इतिहास | AF34: इतिहास | AH34: 5 | AI34: मराठी | AJ34: मराठी | AK34: मराठी | AL34: मराठी | AM34: मराठी | AN34: मराठी | AP34: 5 | AU34: विज्ञान | AV34: विज्ञान | AX34: 5 | AY34: मराठी | AZ34: मराठी | BA34: मराठी | BB34: मराठी | BC34: मराठी | BF34: 5 | BK34: इंग्रजी | BL34: इंग्रजी | BN34: 5 | BO34: परिसर 2 | BP34: परिसर 2 | BQ34: परिसर 2 | BR34: परिसर 2 | BS34: परिसर 2
S35: 8 वी अ | T35: 8 वी अ | U35: 8 वी अ | V35: 8 वी अ | X35: 6 वी अ | AC35: 9 वी अ | AD35: 9 वी अ | AE35: 9 वी अ | AF35: 9 वी अ | AI35: 7 वी अ | AJ35: 7 वी अ | AK35: 7 वी अ | AL35: 7 वी अ | AM35: 7 वी अ | AN35: 7 वी अ | AU35: 10 वी ब | AV35: 10 वी ब | AY35: 5 वी ब | AZ35: 5 वी ब | BA35: 5 वी ब | BB35: 5 वी ब | BC35: 5 वी ब | BK35: 7 वी ब | BL35: 5 वी ब | BO35: 5 वी अ | BP35: 5 वी अ | BQ35: 5 वी अ | BR35: 5 वी अ | BS35: 5 वी अ
B36: 6 | C36: शा.शिक्षण | D36: शा.शिक्षण | E36: शा.शिक्षण | F36: शा.शिक्षण | G36: हिंदी | H36: शा.शिक्षण | J36: 6 | K36: जलसुराक्षा | L36: जलसुराक्षा | M36: समाजशास्त्र | N36: समाजशास्त्र | R36: 6 | S36: शा.शिक्षण | T36: शा.शिक्षण | X36: शा.शिक्षण | Z36: 6 | AA36: इंग्रजी | AB36: इंग्रजी | AC36: इंग्रजी | AD36: इंग्रजी | AE36: इंग्रजी | AF36: इंग्रजी | AH36: 6 | AI36: भूगोल | AJ36: भूगोल | AK36: भूगोल | AL36: भूगोल | AM36: भूगोल | AP36: 6 | AQ36: विज्ञान | AR36: विज्ञान | AS36: विज्ञान | AT36: विज्ञान | AU36: विज्ञान | AV36: गणित | AX36: 6 | BD36: मराठी | BF36: 6 | BG36: इंग्रजी | BH36: इंग्रजी | BI36: इंग्रजी | BJ36: इंग्रजी | BK36: इंग्रजी | BN36: 6
C37: 6 वी ब | D37: 6 वी ब | E37: 6 वी ब | F37: 6 वी ब | G37: 9 वी अ | H37: 10 वी ब | K37: 9 वी अ | L37: 9 वी अ | M37: 6 वी अ | N37: 6 वी अ | S37: 6 वी अ | T37: 6 वी अ | X37: 10 वी अ | AA37: 8 वी ब | AB37: 8 वी ब | AC37: 8 वी ब | AD37: 8 वी ब | AE37: 8 वी ब | AF37: 8 वी ब | AI37: 9 वी ब | AJ37: 9 वी ब | AK37: 9 वी अ | AL37: 9 वी अ | AM37: 9 वी ब | AQ37: 10 वी ब | AR37: 10 वी ब | AS37: 10 वी ब | AT37: 10 वी ब | AU37: 10 वी ब | AV37: 9 वी ब | BD37: 5 वी ब | BG37: 5 वी अ | BH37: 5 वी अ | BI37: 5 वी अ | BJ37: 5 वी अ | BK37: 5 वी अ
B38: 7 | C38: शा.शिक्षण | F38: शा.शिक्षण | G38: शा.शिक्षण | H38: शा.शिक्षण | J38: 7 | K38: परिसर 2 | L38: परिसर 2 | M38: परिसर 2 | N38: परिसर 2 | P38: परिसर 2 | R38: 7 | T38: शा.शिक्षण | U38: शा.शिक्षण | V38: शा.शिक्षण | W38: शा.शिक्षण | X38: शा.शिक्षण | Z38: 7 | AE38: इंग्रजी | AF38: इंग्रजी | AH38: 7 | AI38: भूगोल | AJ38: भूगोल | AK38: भूगोल | AM38: भूगोल | AP38: 7 | AQ38: विज्ञान | AR38: विज्ञान | AS38: विज्ञान | AT38: विज्ञान | AU38: विज्ञान | AX38: 7 | AZ38: कार्यशिक्षण | BA38: कार्यशिक्षण | BB38: कार्यशिक्षण | BC38: समाजशास्त्र | BD38: समाजशास्त्र | BF38: 7 | BG38: इंग्रजी | BH38: इंग्रजी | BI38: इंग्रजी | BJ38: इंग्रजी | BL38: इंग्रजी | BN38: 7 | BO38: विज्ञान | BP38: विज्ञान | BQ38: विज्ञान | BR38: विज्ञान | BS38: विज्ञान
C39: 8 वी ब | F39: 10 वी ब | G39: 5 वी अ | H39: 5 वी अ | K39: 5 वी ब | L39: 5 वी ब | M39: 5 वी ब | N39: 5 वी ब | P39: 5 वी ब | T39: 7 वी अ | U39: 7 वी अ | V39: 7 वी अ | W39: 5 वी ब | X39: 6 वी अ | AE39: 10 वी ब | AF39: 9 वी अ | AI39: 10 वी ब | AJ39: 10 वी ब | AK39: 10 वी ब | AM39: 9 वी अ | AQ39: 9 वी ब | AR39: 9 वी ब | AS39: 9 वी ब | AT39: 9 वी ब | AU39: 9 वी ब | AZ39: 5 वी अ | BA39: 5 वी अ | BB39: 5 वी अ | BC39: 7 वी अ | BD39: 7 वी अ | BG39: 7 वी ब | BH39: 7 वी ब | BI39: 7 वी ब | BJ39: 7 वी ब | BL39: 7 वी ब | BO39: 6 वी अ | BP39: 6 वी अ | BQ39: 6 वी अ | BR39: 6 वी अ | BS39: 6 वी अ
B40: 8 | C40: शा.शिक्षण | D40: शा.शिक्षण | E40: शा.शिक्षण | F40: शा.शिक्षण | G40: शा.शिक्षण | H40: शा.शिक्षण | J40: 8 | K40: परिसर 2 | L40: हिंदी | M40: हिंदी | N40: जलसुरक्षा | R40: 8 | S40: शा.शिक्षण | T40: शा.शिक्षण | U40: शा.शिक्षण | V40: शा.शिक्षण | W40: शा.शिक्षण | X40: शा.शिक्षण | Z40: 8 | AA40: जलसुरक्षा | AD40: जलसुरक्षा | AE40: जलसुरक्षा | AH40: 8 | AP40: 8 | AQ40: गणित | AT40: विज्ञान | AU40: विज्ञान | AV40: विज्ञान | AX40: 8 | AZ40: समाजशास्त्र | BA40: समाजशास्त्र | BB40: समाजशास्त्र | BC40: समाजशास्त्र | BF40: 8 | BG40: समाजशास्त्र | BH40: समाजशास्त्र | BI40: समाजशास्त्र | BJ40: समाजशास्त्र | BK40: इंग्रजी | BL40: स्का./ गाईड | BN40: 8 | BO40: परिसर 2 | BP40: गणित | BQ40: विज्ञान | BR40: गणित | BS40: विज्ञान | BT40: गणित
C41: 9 वी अ | D41: 9 वी अ | E41: 9 वी अ | F41: 8 वी ब | G41: 8 वी ब | H41: 10 वी ब | K41: 5 वी ब | L41: 5 वी अ | M41: 5 वी अ | N41: 9 वी अ | S41: 9 वी ब | T41: 9 वी ब | U41: 9 वी ब | V41: 10 वी अ | W41: 10 वी अ | X41: 5 वी ब | AA41: 10 वी ब | AD41: 10 वी ब | AE41: 10 वी ब | AQ41: 8 वी ब | AT41: 9 वी ब | AU41: 9 वी ब | AV41: 8 वी ब | AZ41: 7 वी अ | BA41: 7 वी अ | BB41: 7 वी अ | BC41: 7 वी अ | BG41: 6 वी ब | BH41: 6 वी ब | BI41: 6 वी ब | BJ41: 6 वी ब | BK41: 5 वी अ | BL41: 9 वी अ | BO41: 5 वी अ | BP41: 6 वी अ | BQ41: 6 वी अ | BR41: 5 वी अ | BS41: 6 वी अ | BT41: 5 वी अ

Sheet शिक्षक विषय वाटप
A1: क्रांतिवीर वसंतराव नारायणराव नाईक शिक्षण प्रसारक संस्था नाशिक,संचलित
A2: माध्यमिक व उच्च माध्यमिक विद्यामंदिर,राजापूर ता.येवला जि.नाशिक
A3: शिक्षक विषय व वर्ग वाटप पत्रक सन 2026-27
A4: अ.नं. | B4: शिक्षकांचे नावे | C4: पद | D4: वर्गशिक्षक | E4: मराठी | G4: हिंदी | I4: इंग्रजी | K4: गणित | M4: परिसर 1 | O4: परिसर 2 | Q4: विज्ञान | S4: समाजशास्त्र | U4: इतिहास | W4: भूगोल | Y4: कला | AA4: शा.शिक्षण | AC4: कार्यशिक्षण | AE4: जलसुरक्षा | AG4: स्का./ गाईड | AI4: एकूण तासिका
E5: वर्ग | F5: तास | G5: वर्ग | H5: तास | I5: वर्ग | J5: तास | K5: वर्ग | L5: तास | M5: वर्ग | N5: तास | O5: वर्ग | P5: तास | Q5: वर्ग | R5: तास | S5: वर्ग | T5: तास | U5: वर्ग | V5: तास | W5: वर्ग | X5: तास | Y5: वर्ग | Z5: तास | AA5: वर्ग | AB5: तास | AC5: वर्ग | AD5: तास | AE5: वर्ग | AF5: तास | AG5: वर्ग | AH5: तास
A6: 1 | B6: गिते एस.एस. | C6: प्राचार्य | D6: - | F6: 0 | H6: 0 | J6: 0 | L6: 0 | N6: 0 | P6: 0 | R6: 0 | T6: 0 | V6: 0 | X6: 0 | Z6: 0 | AA6: 7ब(4) | AB6: 4 | AC6: 5ब(3), 7ब(2), 8ब(2) | AD6: 7 | AF6: 0 | AG6: 9अ(1) | AH6: 1 | AI6: 12
A7: 2 | B7: वाघ आर.बी. | C7: पर्यवेक्षक | D7: - | F7: 0 | G7: 9अ(6) | H7: 6 | J7: 0 | L7: 0 | N7: 0 | P7: 0 | R7: 0 | T7: 0 | V7: 0 | X7: 0 | Z7: 0 | AA7: 5अ(4), 6ब(4), 8ब(4), 9अ(3), 10ब(3) | AB7: 18 | AD7: 0 | AF7: 0 | AH7: 0 | AI7: 24
A8: 3 | B8: वाघ एस.एन. | C8: उपशिक्षक | D8: - | F8: 0 | H8: 0 | J8: 0 | L8: 0 | N8: 0 | P8: 0 | R8: 0 | T8: 0 | V8: 0 | X8: 0 | Y8: 5अ(3), 5ब(3), 6अ(4), 6ब(4), 7अ(4), 7ब(4), 8अ(4), 8ब(4) | Z8: 30 | AB8: 0 | AC8: 6अ(2) | AD8: 2 | AF8: 0 | AH8: 0 | AI8: 32
A9: 4 | B9: सानप बी.डी. | C9: उपशिक्षक | D9: 6 वी ब | E9: 6ब(6) | F9: 6 | G9: 5अ(6) | H9: 6 | J9: 0 | L9: 0 | M9: 5ब(6) | N9: 6 | O9: 5ब(6) | P9: 6 | R9: 0 | S9: 6अ(6) | T9: 6 | V9: 0 | X9: 0 | Z9: 0 | AB9: 0 | AD9: 0 | AE9: 9अ(3) | AF9: 3 | AH9: 0 | AI9: 33
A10: 5 | B10: काकड आर.बी. | C10: उपशिक्षक | D10: 9 वी अ | E10: 6अ(6), 9अ(6) | F10: 12 | H10: 0 | J10: 0 | L10: 0 | N10: 0 | P10: 0 | R10: 0 | S10: 8अ(6), 8ब(6) | T10: 12 | U10: 10अ(4), 10ब(4) | V10: 8 | X10: 0 | Z10: 0 | AB10: 0 | AC10: 8अ(2) | AD10: 2 | AF10: 0 | AH10: 0 | AI10: 34
A11: 6 | B11: वाघ व्ही.व्ही. | C11: उपशिक्षक | D11: - | F11: 0 | G11: 7अ(6), 10ब(6) | H11: 12 | J11: 0 | L11: 0 | N11: 0 | P11: 0 | R11: 0 | T11: 0 | V11: 0 | X11: 0 | Z11: 0 | AA11: 5ब(4), 6अ(4), 7अ(4), 8अ(4), 9ब(3), 10अ(3) | AB11: 22 | AD11: 0 | AF11: 0 | AH11: 0 | AI11: 34
A12: 7 | B12: घुगे एस.आर. | C12: उपशिक्षक | D12: - | F12: 0 | H12: 0 | I12: 6अ(6), 7अ(6), 9ब(7), 10अ(7) | J12: 26 | L12: 0 | N12: 0 | P12: 0 | R12: 0 | T12: 0 | V12: 0 | X12: 0 | Z12: 0 | AB12: 0 | AC12: 6ब(2) | AD12: 2 | AE12: 9ब(3), 10अ(3) | AF12: 6 | AH12: 0 | AI12: 34
A13: 8 | B13: जगताप एस.डी. | C13: उपशिक्षक | D13: 8 वी अ | F13: 0 | H13: 0 | I13: 8अ(6), 8ब(6), 9अ(7), 10ब(7) | J13: 26 | L13: 0 | N13: 0 | P13: 0 | R13: 0 | T13: 0 | U13: 9अ(4) | V13: 4 | X13: 0 | Z13: 0 | AB13: 0 | AD13: 0 | AE13: 10ब(3) | AF13: 3 | AH13: 0 | AI13: 33
A14: 9 | B14: ठोंबरे एल.एस. | C14: उपशिक्षक | D14: 7 वी ब | E14: 10ब(6) | F14: 6 | G14: 6ब(6), 8ब(6) | H14: 12 | J14: 0 | L14: 0 | N14: 0 | P14: 0 | R14: 0 | S14: 7ब(6) | T14: 6 | U14: 9ब(4) | V14: 4 | X14: 0 | Z14: 0 | AB14: 0 | AC14: 7अ(2) | AD14: 2 | AF14: 0 | AG14: 10अ(2), 10ब(2) | AH14: 4 | AI14: 34
A15: 10 | B15: पानसरे व्ही.व्ही. | C15: उपशिक्षक | D15: 10 वी अ | E15: 7अ(6), 8अ(6), 8ब(6), 10अ(6) | F15: 24 | H15: 0 | J15: 0 | L15: 0 | N15: 0 | P15: 0 | R15: 0 | T15: 0 | V15: 0 | W15: 9अ(3), 9ब(3), 10ब(3) | X15: 9 | Z15: 0 | AB15: 0 | AD15: 0 | AF15: 0 | AH15: 0 | AI15: 33
A16: 11 | B16: गडाख एस.एस. | C16: उपशिक्षक | D16: 10 वी ब | F16: 0 | H16: 0 | J16: 0 | K16: 10अ(7), 10ब(7) | L16: 14 | N16: 0 | P16: 0 | Q16: 7अ(7), 8अ(7), 9अ(7) | R16: 21 | T16: 0 | V16: 0 | X16: 0 | Z16: 0 | AB16: 0 | AD16: 0 | AF16: 0 | AH16: 0 | AI16: 35
A17: 12 | B17: कुलकर्णी एम.एल. | C17: उपशिक्षक | D17: 8 वी ब | F17: 0 | H17: 0 | J17: 0 | K17: 8ब(7), 9ब(7) | L17: 14 | N17: 0 | P17: 0 | Q17: 8ब(7), 9ब(7), 10ब(7) | R17: 21 | T17: 0 | V17: 0 | X17: 0 | Z17: 0 | AB17: 0 | AD17: 0 | AF17: 0 | AH17: 0 | AI17: 35
A18: 13 | B18: गिते जे.ए. | C18: उपशिक्षिका | D18: 7 वी अ | F18: 0 | H18: 0 | J18: 0 | K18: 7अ(7), 8अ(7), 9अ(7) | L18: 21 | N18: 0 | P18: 0 | Q18: 7ब(7), 10अ(7) | R18: 14 | T18: 0 | V18: 0 | X18: 0 | Z18: 0 | AB18: 0 | AD18: 0 | AF18: 0 | AH18: 0 | AI18: 35
A19: 14 | B19: सानप जी.बी. | C19: उपशिक्षक | D19: 9 वी ब | E19: 5अ(6), 5ब(6), 7ब(6), 9ब(6) | F19: 24 | H19: 0 | J19: 0 | L19: 0 | N19: 0 | P19: 0 | R19: 0 | S19: 7अ(6) | T19: 6 | V19: 0 | X19: 0 | Z19: 0 | AB19: 0 | AC19: 5अ(3) | AD19: 3 | AF19: 0 | AH19: 0 | AI19: 33
A20: 15 | B20: दराडे एस.एल. | C20: उपशिक्षक | D20: 6 वी अ | F20: 0 | G20: 6अ(6), 7ब(6), 8अ(6), 9ब(6), 10अ(6) | H20: 30 | J20: 0 | L20: 0 | N20: 0 | P20: 0 | R20: 0 | T20: 0 | V20: 0 | W20: 10अ(3) | X20: 3 | Z20: 0 | AB20: 0 | AD20: 0 | AF20: 0 | AH20: 0 | AI20: 33
A21: 16 | B21: चौधरी एस.बी. | C21: उपशिक्षिका | D21: - | F21: 0 | H21: 0 | I21: 5अ(6), 5ब(6), 6ब(6), 7ब(6) | J21: 24 | L21: 0 | N21: 0 | P21: 0 | R21: 0 | S21: 6ब(6) | T21: 6 | V21: 0 | X21: 0 | Z21: 0 | AB21: 0 | AD21: 0 | AF21: 0 | AG21: 9अ(1), 9ब(2) | AH21: 3 | AI21: 33
A22: 17 | B22: बोडखे आर.एस. | C22: उपशिक्षक | D22: 5 वी ब | F22: 0 | G22: 5ब(6) | H22: 6 | J22: 0 | K22: 5ब(8), 6ब(7), 7ब(7) | L22: 22 | N22: 0 | P22: 0 | Q22: 6ब(7) | R22: 7 | T22: 0 | V22: 0 | X22: 0 | Z22: 0 | AB22: 0 | AD22: 0 | AF22: 0 | AH22: 0 | AI22: 35
A23: 18 | B23: दराडे डी.डी. | C23: उपशिक्षक | D23: 5 वी अ | F23: 0 | H23: 0 | J23: 0 | K23: 5अ(8), 6अ(7) | L23: 15 | M23: 5अ(6) | N23: 6 | O23: 5अ(6) | P23: 6 | Q23: 6अ(7) | R23: 7 | T23: 0 | V23: 0 | X23: 0 | Z23: 0 | AB23: 0 | AD23: 0 | AF23: 0 | AH23: 0 | AI23: 34
D24: एकूण तासिका | F24: 72 | H24: 72 | J24: 76 | L24: 86 | N24: 12 | P24: 12 | R24: 70 | T24: 36 | V24: 16 | X24: 12 | Z24: 30 | AB24: 44 | AD24: 18 | AF24: 12 | AH24: 8 | AI24: 576

Sheet वर्ग विषय शिक्षक
B1: क्रांतिवीर वसंतराव नारायणराव नाईक शिक्षण प्रसारक संस्था नाशिक,संचलित
B2: माध्यमिक व उच्च माध्यमिक विद्यामंदिर,राजापूर ता.येवला जि.नाशिक
B3: शिक्षक विषय व वर्ग वाटप पत्रक सन 2026-27
B4: इयत्ता/तुकडी | D4: मराठी | E4: हिंदी | F4: इंग्रजी | G4: गणित | H4: परिसर 1 | I4: परिसर 2 | J4: विज्ञान | K4: समाजशास्त्र | L4: इतिहास | M4: भूगोल | N4: कला | O4: शा.शिक्षण | P4: कार्यशिक्षण | Q4: जलसुरक्षा | R4: स्का./ गाईड
B5: 5 वी | C5: अ | D5: सानप जी.बी. | E5: सानप बी.डी. | F5: चौधरी एस.बी. | G5: दराडे डी.डी. | H5: दराडे डी.डी. | I5: दराडे डी.डी. | N5: वाघ एस.एन. | O5: वाघ आर.बी. | P5: सानप जी.बी.
B6: 5 वी | C6: ब | D6: सानप जी.बी. | E6: बोडखे आर.एस. | F6: चौधरी एस.बी. | G6: बोडखे आर.एस. | H6: सानप बी.डी. | I6: सानप बी.डी. | N6: वाघ एस.एन. | O6: वाघ व्ही.व्ही. | P6: गिते एस.एस.
B7: 6 वी | C7: अ | D7: काकड आर.बी. | E7: दराडे एस.एल. | F7: घुगे एस.आर. | G7: दराडे डी.डी. | J7: दराडे डी.डी. | K7: सानप बी.डी. | N7: वाघ एस.एन. | O7: वाघ व्ही.व्ही. | P7: वाघ एस.एन.
B8: 6 वी | C8: ब | D8: सानप बी.डी. | E8: ठोंबरे एल.एस. | F8: चौधरी एस.बी. | G8: बोडखे आर.एस. | J8: बोडखे आर.एस. | K8: चौधरी एस.बी. | N8: वाघ एस.एन. | O8: वाघ आर.बी. | P8: घुगे एस.आर.
B9: 7 वी | C9: अ | D9: पानसरे व्ही.व्ही. | E9: वाघ व्ही.व्ही. | F9: घुगे एस.आर. | G9: गिते जे.ए. | J9: गडाख एस.एस. | K9: सानप जी.बी. | N9: वाघ एस.एन. | O9: वाघ व्ही.व्ही. | P9: ठोंबरे एल.एस.
B10: 7 वी | C10: ब | D10: सानप जी.बी. | E10: दराडे एस.एल. | F10: चौधरी एस.बी. | G10: बोडखे आर.एस. | J10: गिते जे.ए. | K10: ठोंबरे एल.एस. | N10: वाघ एस.एन. | O10: गिते एस.एस. | P10: गिते एस.एस.
B11: 8 वी | C11: अ | D11: पानसरे व्ही.व्ही. | E11: दराडे एस.एल. | F11: जगताप एस.डी. | G11: गिते जे.ए. | J11: गडाख एस.एस. | K11: काकड आर.बी. | N11: वाघ एस.एन. | O11: वाघ व्ही.व्ही. | P11: काकड आर.बी.
B12: 8 वी | C12: ब | D12: पानसरे व्ही.व्ही. | E12: ठोंबरे एल.एस. | F12: जगताप एस.डी. | G12: कुलकर्णी एम.एल. | J12: कुलकर्णी एम.एल. | K12: काकड आर.बी. | N12: वाघ एस.एन. | O12: वाघ आर.बी. | P12: गिते एस.एस.
B13: 9 वी | C13: अ | D13: काकड आर.बी. | E13: वाघ आर.बी. | F13: जगताप एस.डी. | G13: गिते जे.ए. | J13: गडाख एस.एस. | L13: जगताप एस.डी. | M13: पानसरे व्ही.व्ही. | O13: वाघ आर.बी. | Q13: सानप बी.डी. | R13: गिते एस.एस.(1), चौधरी एस.बी.(1)
B14: 9 वी | C14: ब | D14: सानप जी.बी. | E14: दराडे एस.एल. | F14: घुगे एस.आर. | G14: कुलकर्णी एम.एल. | J14: कुलकर्णी एम.एल. | L14: ठोंबरे एल.एस. | M14: पानसरे व्ही.व्ही. | O14: वाघ व्ही.व्ही. | Q14: घुगे एस.आर. | R14: चौधरी एस.बी.
B15: 10 वी | C15: अ | D15: पानसरे व्ही.व्ही. | E15: दराडे एस.एल. | F15: घुगे एस.आर. | G15: गडाख एस.एस. | J15: गिते जे.ए. | L15: काकड आर.बी. | M15: दराडे एस.एल. | O15: वाघ व्ही.व्ही. | Q15: घुगे एस.आर. | R15: ठोंबरे एल.एस.
B16: 10 वी | C16: ब | D16: ठोंबरे एल.एस. | E16: वाघ व्ही.व्ही. | F16: जगताप एस.डी. | G16: गडाख एस.एस. | J16: कुलकर्णी एम.एल. | L16: काकड आर.बी. | M16: पानसरे व्ही.व्ही. | O16: वाघ आर.बी. | Q16: जगताप एस.डी. | R16: ठोंबरे एल.एस.

Sheet सोमवार
A1: सोमवार - वारनिहाय सर्व वर्ग वेळापत्रक
A2: माध्यमिक व उच्च माध्यमिक विद्यामंदिर, राजापूर | 5 वी अ ते 10 वी ब | तास 1 ते 8
A3: तास | B3: 5 वी अ | C3: 5 वी ब | D3: 6 वी अ | E3: 6 वी ब | F3: 7 वी अ | G3: 7 वी ब | H3: 8 वी अ | I3: 8 वी ब | J3: 9 वी अ | K3: 9 वी ब | L3: 10 वी अ | M3: 10 वी ब
A4: 1 | B4: =IF(OR(वर्गवेळापत्रक!C4="",वर्गवेळापत्रक!C5=""),"",वर्गवेळापत्रक!C4&" - "&वर्गवेळापत्रक!C5) -> गणित - दराडे डी.डी. | C4: =IF(OR(वर्गवेळापत्रक!C25="",वर्गवेळापत्रक!C26=""),"",वर्गवेळापत्रक!C25&" - "&वर्गवेळापत्रक!C26) -> गणित - बोडखे आर.एस. | D4: =IF(OR(वर्गवेळापत्रक!K4="",वर्गवेळापत्रक!K5=""),"",वर्गवेळापत्रक!K4&" - "&वर्गवेळापत्रक!K5) -> हिंदी - दराडे एस.एल. | E4: =IF(OR(वर्गवेळापत्रक!K25="",वर्गवेळापत्रक!K26=""),"",वर्गवेळापत्रक!K25&" - "&वर्गवेळापत्रक!K26) -> मराठी - सानप बी.डी. | F4: =IF(OR(वर्गवेळापत्रक!S4="",वर्गवेळापत्रक!S5=""),"",वर्गवेळापत्रक!S4&" - "&वर्गवेळापत्रक!S5) -> गणित - गिते जे.ए. | G4: =IF(OR(वर्गवेळापत्रक!S25="",वर्गवेळापत्रक!S26=""),"",वर्गवेळापत्रक!S25&" - "&वर्गवेळापत्रक!S26) -> समाजशास्त्र - ठोंबरे एल.एस. | H4: =IF(OR(वर्गवेळापत्रक!AA4="",वर्गवेळापत्रक!AA5=""),"",वर्गवेळापत्रक!AA4&" - "&वर्गवेळापत्रक!AA5) -> इंग्रजी - जगताप एस.डी. | I4: =IF(OR(वर्गवेळापत्रक!AA25="",वर्गवेळापत्रक!AA26=""),"",वर्गवेळापत्रक!AA25&" - "&वर्गवेळापत्रक!AA26) -> गणित - कुलकर्णी एम.एल. | J4: =IF(OR(वर्गवेळापत्रक!AI4="",वर्गवेळापत्रक!AI5=""),"",वर्गवेळापत्रक!AI4&" - "&वर्गवेळापत्रक!AI5) -> मराठी - काकड आर.बी. | K4: =IF(OR(वर्गवेळापत्रक!AI25="",वर्गवेळापत्रक!AI26=""),"",वर्गवेळापत्रक!AI25&" - "&वर्गवेळापत्रक!AI26) -> मराठी - सानप जी.बी. | L4: =IF(OR(वर्गवेळापत्रक!AQ4="",वर्गवेळापत्रक!AQ5=""),"",वर्गवेळापत्रक!AQ4&" - "&वर्गवेळापत्रक!AQ5) -> मराठी - पानसरे व्ही.व्ही. | M4: =IF(OR(वर्गवेळापत्रक!AQ25="",वर्गवेळापत्रक!AQ26=""),"",वर्गवेळापत्रक!AQ25&" - "&वर्गवेळापत्रक!AQ26) -> गणित - गडाख एस.एस.
A5: 2 | B5: =IF(OR(वर्गवेळापत्रक!C6="",वर्गवेळापत्रक!C7=""),"",वर्गवेळापत्रक!C6&" - "&वर्गवेळापत्रक!C7) -> हिंदी - सानप बी.डी. | C5: =IF(OR(वर्गवेळापत्रक!C27="",वर्गवेळापत्रक!C28=""),"",वर्गवेळापत्रक!C27&" - "&वर्गवेळापत्रक!C28) -> कार्यशिक्षण - गिते एस.एस. | D5: =IF(OR(वर्गवेळापत्रक!K6="",वर्गवेळापत्रक!K7=""),"",वर्गवेळापत्रक!K6&" - "&वर्गवेळापत्रक!K7) -> मराठी - काकड आर.बी. | E5: =IF(OR(वर्गवेळापत्रक!K27="",वर्गवेळापत्रक!K28=""),"",वर्गवेळापत्रक!K27&" - "&वर्गवेळापत्रक!K28) -> इंग्रजी - चौधरी एस.बी. | F5: =IF(OR(वर्गवेळापत्रक!S6="",वर्गवेळापत्रक!S7=""),"",वर्गवेळापत्रक!S6&" - "&वर्गवेळापत्रक!S7) -> कला - वाघ एस.एन. | G5: =IF(OR(वर्गवेळापत्रक!S27="",वर्गवेळापत्रक!S28=""),"",वर्गवेळापत्रक!S27&" - "&वर्गवेळापत्रक!S28) -> हिंदी - दराडे एस.एल. | H5: =IF(OR(वर्गवेळापत्रक!AA6="",वर्गवेळापत्रक!AA7=""),"",वर्गवेळापत्रक!AA6&" - "&वर्गवेळापत्रक!AA7) -> गणित - गिते जे.ए. | I5: =IF(OR(वर्गवेळापत्रक!AA27="",वर्गवेळापत्रक!AA28=""),"",वर्गवेळापत्रक!AA27&" - "&वर्गवेळापत्रक!AA28) -> मराठी - पानसरे व्ही.व्ही. | J5: =IF(OR(वर्गवेळापत्रक!AI6="",वर्गवेळापत्रक!AI7=""),"",वर्गवेळापत्रक!AI6&" - "&वर्गवेळापत्रक!AI7) -> इंग्रजी - जगताप एस.डी. | K5: =IF(OR(वर्गवेळापत्रक!AI27="",वर्गवेळापत्रक!AI28=""),"",वर्गवेळापत्रक!AI27&" - "&वर्गवेळापत्रक!AI28) -> इंग्रजी - घुगे एस.आर. | L5: =IF(OR(वर्गवेळापत्रक!AQ6="",वर्गवेळापत्रक!AQ7=""),"",वर्गवेळापत्रक!AQ6&" - "&वर्गवेळापत्रक!AQ7) -> गणित - गडाख एस.एस. | M5: =IF(OR(वर्गवेळापत्रक!AQ27="",वर्गवेळापत्रक!AQ28=""),"",वर्गवेळापत्रक!AQ27&" - "&वर्गवेळापत्रक!AQ28) -> मराठी - ठोंबरे एस.एल.
